Workbook

Sheet README
B2: Hailo-10H 10H 워크로드 실험 — hailortcli 계측 유무에 따른 추론 성능 비교
B3: 7개 워크로드 조합 x 3회 = 21런, 두 실험을 공통 열에서 1:1 비교
B5: 비교 대상
B6: A. CLI OFF (기준) | C6: results_det_seg_pose_workload_21runs.csv — 원본 스윕 CSV의 세트 C(38~58행). HRTT 대체 열 없음. 2026-08-28 측정.
B7: B. CLI ON | C7: results_det_seg_pose_workload_full.csv — 8L과 열 구성을 맞춘 확장 CSV. npu_percent 등을 채우려고 벤치가 hailortcli monitor를 자식 프로세스로 띄움. 2026-08-31 측정.
B8: 참고. 재현성 | C8: results_det_seg_pose_workload_setA_21runs.csv — 같은 CLI OFF 조건의 세트 A. A와 C의 차이가 곧 "측정 노이즈"의 크기다.
B10: 비교한 공통 열
B11: 지연시간 | C11: CLI OFF: det/seg/pose_avg_latency_ms <-> CLI ON: det/seg/pose_latency_ms (둘 다 run_async 제출~wait 완료, 전처리 제외)
B12: FPS | C12: CLI OFF: det/seg/pose_fps <-> CLI ON: avg_fps_det/seg/pose (둘 다 프레임 수 / 워커 전체 시간, 전처리 포함)
B13: 시스템 | C13: cpu_percent, mem_percent (호스트 전체, /proc/stat 300ms 샘플 · /proc/meminfo)
B14: 프레임 수 | C14: det/seg/pose_frame_count — 양쪽 모두 673으로 동일하므로 차이 계산에서 제외
B15: 비교 제외 | C15: batch/threshold/priority/timeout(설정값), npu_percent·ctx_switches·max_latency·preprocess·total_time (CLI ON 쪽에만 존재) → "CLI전용지표" 시트에 참고로 수록
B17: 계산 방법
B18: 평균 / 표준편차 | C18: 조건별 3런에 대한 AVERAGE / STDEV. 모든 셀이 원본 시트를 참조하는 수식이며, 하드코딩된 값이 아니다.
B19: 차이 | C19: CLI ON 평균 - CLI OFF 평균
B20: 차이율(%) | C20: (CLI ON 평균 - CLI OFF 평균) / CLI OFF 평균. 지연시간은 +가 느려짐, FPS는 +가 빨라짐을 뜻한다.
B21: 노이즈 판정 | C21: |차이| 가 두 실험의 표준편차 합보다 크면 "노이즈 초과", 아니면 "노이즈 수준"으로 표기
B23: !! 해석 시 주의
B24: 교란 요인 1 | C24: CLI ON 실험(2026-08-31)은 hailortcli monitor만 켠 것이 아니라 host_trace 타임라인 수집(--trace_dir traces)도 함께 켜져 있었다. 따라서 여기서 나오는 차이는 "hailortcli 단독 효과"가 아니라 "hailortcli monitor + 타임라인 계측"의 합이다. CLI만의 효과를 분리하려면 --no_npu_monitor 로 타임라인만 켠 런이 한 세트 더 필요하다.
B25: 교란 요인 2 | C25: 두 실험은 같은 날이 아니다(08-28 vs 08-31). 그 사이 벤치 바이너리도 갱신되었다(src/hailo10h_sched_bench.cpp 08-31 수정). 열 정의는 문서상 동일하지만, 재빌드 자체의 영향은 배제되지 않는다.
B26: 교란 요인 3 | C26: mem_percent는 호스트 전체 사용률이라 벤치와 무관한 백그라운드 변동을 포함한다. 세트 A와 세트 C 사이에서도 이미 1.5%p 이상 벌어진다(재현성 시트 참고). 차이율을 성능 지표처럼 읽지 말 것.
B27: 표본 수 | C27: 조건당 3런뿐이다. 표준편차는 참고용이며 통계적 검정을 대신하지 않는다.
B29: 출처 폴더 | C29: C:\Users\sset0\jungmin-claude\StudentExperiment\NPUscheduler\hailo_10h\experiments\2026-08-24_det_seg_pose_workload_exp1\csv

Sheet 원본_CLI_OFF
A1: label | B1: run_id | C1: use_det | D1: use_seg | E1: use_pose | F1: det_frame_count | G1: det_latency_ms | H1: det_fps | I1: seg_frame_count | J1: seg_latency_ms | K1: seg_fps | L1: pose_frame_count | M1: pose_latency_ms | N1: pose_fps | O1: cpu_percent | P1: mem_percent
A2: det | B2: 1 | C2: 1 | D2: 0 | E2: 0 | F2: 673 | G2: 17.8304 | H2: 42.3927 | O2: 12.5632 | P2: 6.76675
A3: det | B3: 2 | C3: 1 | D3: 0 | E3: 0 | F3: 673 | G3: 17.8411 | H3: 42.3239 | O3: 12.9354 | P3: 6.7556
A4: det | B4: 3 | C4: 1 | D4: 0 | E4: 0 | F4: 673 | G4: 17.8359 | H4: 42.3196 | O4: 12.6818 | P4: 6.89661
A5: seg | B5: 1 | C5: 0 | D5: 1 | E5: 0 | I5: 673 | J5: 22.8666 | K5: 34.6485 | O5: 11.2007 | P5: 7.13976
A6: seg | B6: 2 | C6: 0 | D6: 1 | E6: 0 | I6: 673 | J6: 22.7856 | K6: 34.7642 | O6: 10.8915 | P6: 6.86516
A7: seg | B7: 3 | C7: 0 | D7: 1 | E7: 0 | I7: 673 | J7: 22.8762 | K7: 34.6504 | O7: 10.6852 | P7: 6.86174
A8: pose | B8: 1 | C8: 0 | D8: 0 | E8: 1 | L8: 673 | M8: 17.8263 | N8: 42.339 | O8: 13.0519 | P8: 6.98292
A9: pose | B9: 2 | C9: 0 | D9: 0 | E9: 1 | L9: 673 | M9: 17.8201 | N9: 42.3792 | O9: 12.3875 | P9: 7.01595
A10: pose | B10: 3 | C10: 0 | D10: 0 | E10: 1 | L10: 673 | M10: 17.8074 | N10: 42.4043 | O10: 12.7382 | P10: 6.93609
A11: det_seg | B11: 1 | C11: 1 | D11: 1 | E11: 0 | F11: 673 | G11: 25.1379 | H11: 32.0692 | I11: 673 | J11: 25.1126 | K11: 32.0779 | O11: 19.196 | P11: 7.70133
A12: det_seg | B12: 2 | C12: 1 | D12: 1 | E12: 0 | F12: 673 | G12: 25.1973 | H12: 32.1646 | I12: 673 | J12: 25.1336 | K12: 32.1747 | O12: 18.9294 | P12: 7.87561
A13: det_seg | B13: 3 | C13: 1 | D13: 1 | E13: 0 | F13: 673 | G13: 25.1352 | H13: 31.8643 | I13: 673 | J13: 25.236 | K13: 31.705 | O13: 19.3373 | P13: 8.01206
A14: det_pose | B14: 1 | C14: 1 | D14: 0 | E14: 1 | F14: 673 | G14: 20.7708 | H14: 38.0996 | L14: 673 | M14: 20.7974 | N14: 38.0819 | O14: 21.098 | P14: 7.70003
A15: det_pose | B15: 2 | C15: 1 | D15: 0 | E15: 1 | F15: 673 | G15: 20.648 | H15: 39.0165 | L15: 673 | M15: 20.6479 | N15: 39.0582 | O15: 20.6702 | P15: 7.97209
A16: det_pose | B16: 3 | C16: 1 | D16: 0 | E16: 1 | F16: 673 | G16: 20.753 | H16: 37.5919 | L16: 673 | M16: 20.7897 | N16: 37.5733 | O16: 21.9111 | P16: 7.76571
A17: seg_pose | B17: 1 | C17: 0 | D17: 1 | E17: 1 | I17: 673 | J17: 25.5755 | K17: 31.5674 | L17: 673 | M17: 25.6016 | N17: 31.602 | O17: 18.8527 | P17: 8.41386
A18: seg_pose | B18: 2 | C18: 0 | D18: 1 | E18: 1 | I18: 673 | J18: 25.5398 | K18: 31.5427 | L18: 673 | M18: 25.5175 | N18: 31.7038 | O18: 18.9307 | P18: 8.28194
A19: seg_pose | B19: 3 | C19: 0 | D19: 1 | E19: 1 | I19: 673 | J19: 25.4557 | K19: 31.6393 | L19: 673 | M19: 25.5758 | N19: 31.6292 | O19: 19.3629 | P19: 7.8658
A20: det_seg_pose | B20: 1 | C20: 1 | D20: 1 | E20: 1 | F20: 673 | G20: 25.8857 | H20: 31.7946 | I20: 673 | J20: 25.7333 | K20: 31.8209 | L20: 673 | M20: 25.8202 | N20: 31.811 | O20: 27.0438 | P20: 8.69201
A21: det_seg_pose | B21: 2 | C21: 1 | D21: 1 | E21: 1 | F21: 673 | G21: 26.0548 | H21: 32.0173 | I21: 673 | J21: 25.9916 | K21: 31.9817 | L21: 673 | M21: 25.9367 | N21: 32.112 | O21: 25.5871 | P21: 8.32395
A22: det_seg_pose | B22: 3 | C22: 1 | D22: 1 | E22: 1 | F22: 673 | G22: 25.8685 | H22: 31.3252 | I22: 673 | J22: 25.7296 | K22: 31.3042 | L22: 673 | M22: 25.8232 | N22: 31.2963 | O22: 28.2132 | P22: 8.35405

Sheet 원본_CLI_ON
A1: label | B1: run_id | C1: use_det | D1: use_seg | E1: use_pose | F1: det_frame_count | G1: det_latency_ms | H1: det_fps | I1: seg_frame_count | J1: seg_latency_ms | K1: seg_fps | L1: pose_frame_count | M1: pose_latency_ms | N1: pose_fps | O1: cpu_percent | P1: mem_percent | Q1: npu_percent | R1: run_time_s | S1: voluntary_ctx_switches | T1: nonvoluntary_ctx_switches | U1: max_latency_det | V1: max_latency_seg | W1: max_latency_pose | X1: avg_preprocess_ms_det | Y1: avg_preprocess_ms_seg | Z1: avg_preprocess_ms_pose | AA1: total_time_ms_nopp_det | AB1: total_time_ms_nopp_seg | AC1: total_time_ms_nopp_pose
A2: det | B2: 1 | C2: 1 | D2: 0 | E2: 0 | F2: 673 | G2: 19.0571 | H2: 40.0426 | O2: 13.11 | P2: 8.06216 | Q2: 23.0938 | R2: 16.8074 | S2: 673 | T2: 329 | U2: 41.4337 | X2: 5.8388 | AA2: 24.8959
A3: det | B3: 2 | C3: 1 | D3: 0 | E3: 0 | F3: 673 | G3: 19.1152 | H3: 40.0537 | O3: 12.5524 | P3: 7.89975 | Q3: 23.4375 | R3: 16.8028 | S3: 675 | T3: 147 | U3: 49.4966 | X3: 5.77611 | AA3: 24.8913
A4: det | B4: 3 | C4: 1 | D4: 0 | E4: 0 | F4: 673 | G4: 19.3373 | H4: 39.6516 | O4: 12.1497 | P4: 7.85803 | Q4: 23.2375 | R4: 16.9732 | S4: 675 | T4: 170 | U4: 46.8777 | X4: 5.80686 | AA4: 25.1442
A5: seg | B5: 1 | C5: 0 | D5: 1 | E5: 0 | I5: 673 | J5: 24.7275 | K5: 32.4839 | O5: 10.5739 | P5: 8.10017 | Q5: 23.0105 | R5: 20.7183 | S5: 674 | T5: 259 | V5: 54.4476 | Y5: 5.9801 | AB5: 30.7076
A6: seg | B6: 2 | C6: 0 | D6: 1 | E6: 0 | I6: 673 | J6: 24.573 | K6: 32.6174 | O6: 10.8267 | P6: 8.15555 | Q6: 23.0842 | R6: 20.6335 | S6: 676 | T6: 318 | V6: 55.9049 | Y6: 6.00668 | AB6: 30.5797
A7: seg | B7: 3 | C7: 0 | D7: 1 | E7: 0 | I7: 673 | J7: 24.7931 | K7: 32.8669 | O7: 10.0717 | P7: 8.05102 | Q7: 22.8579 | R7: 20.4769 | S7: 675 | T7: 95 | V7: 61.3205 | Y7: 5.55793 | AB7: 30.3511
A8: pose | B8: 1 | C8: 0 | D8: 0 | E8: 1 | L8: 673 | M8: 19.5584 | N8: 39.3025 | O8: 11.9762 | P8: 8.03792 | Q8: 25.375 | R8: 17.1239 | S8: 674 | T8: 179 | W8: 51.2653 | Z8: 5.80948 | AC8: 25.3679
A9: pose | B9: 2 | C9: 0 | D9: 0 | E9: 1 | L9: 673 | M9: 19.512 | N9: 39.3206 | O9: 12.5338 | P9: 8.01632 | Q9: 25.9813 | R9: 17.116 | S9: 675 | T9: 80 | W9: 44.7164 | Z9: 5.84432 | AC9: 25.3563
A10: pose | B10: 3 | C10: 0 | D10: 0 | E10: 1 | L10: 673 | M10: 19.9401 | N10: 38.712 | O10: 12.4716 | P10: 7.77117 | Q10: 25.1375 | R10: 17.3851 | S10: 673 | T10: 243 | W10: 84.5466 | Z10: 5.81608 | AC10: 25.7562
A11: det_seg | B11: 1 | C11: 1 | D11: 1 | E11: 0 | F11: 673 | G11: 26.7597 | H11: 30.3919 | I11: 673 | J11: 27.9443 | K11: 29.3621 | O11: 18.2176 | P11: 8.31925 | Q11: 43.9714 | R11: 22.9213 | S11: 1370 | T11: 2630 | U11: 83.9263 | V11: 79.3892 | X11: 6.04368 | Y11: 6.03291 | AA11: 32.8034 | AB11: 33.9772
A12: det_seg | B12: 2 | C12: 1 | D12: 1 | E12: 0 | F12: 673 | G12: 26.5455 | H12: 30.5869 | I12: 673 | J12: 27.9759 | K12: 29.2418 | O12: 18.0785 | P12: 8.75173 | Q12: 42.9619 | R12: 23.0154 | S12: 1379 | T12: 2898 | U12: 59.5203 | V12: 57.6908 | X12: 6.05551 | Y12: 6.13408 | AA12: 32.601 | AB12: 34.11
A13: det_seg | B13: 3 | C13: 1 | D13: 1 | E13: 0 | F13: 673 | G13: 27.3251 | H13: 29.875 | I13: 673 | J13: 28.1716 | K13: 29.1235 | O13: 17.8263 | P13: 8.39837 | Q13: 43.8286 | R13: 23.109 | S13: 1371 | T13: 2944 | U13: 120.57 | V13: 86.2702 | X13: 6.05166 | Y13: 6.08706 | AA13: 33.3768 | AB13: 34.2587
A14: det_pose | B14: 1 | C14: 1 | D14: 0 | E14: 1 | F14: 673 | G14: 23.3575 | H14: 34.1348 | L14: 673 | M14: 23.5959 | N14: 33.8967 | O14: 20.3259 | P14: 8.67455 | Q14: 47.6556 | R14: 19.8549 | S14: 1382 | T14: 3003 | U14: 91.4037 | W14: 80.7853 | X14: 5.85053 | Z14: 5.83127 | AA14: 29.208 | AC14: 29.4272
A15: det_pose | B15: 2 | C15: 1 | D15: 0 | E15: 1 | F15: 673 | G15: 23.6293 | H15: 34.7699 | L15: 673 | M15: 23.6854 | N15: 34.6995 | O15: 19.1446 | P15: 8.30725 | Q15: 49.5889 | R15: 19.3956 | S15: 1357 | T15: 702 | U15: 80.1373 | W15: 74.2591 | X15: 5.05004 | Z15: 5.06006 | AA15: 28.6793 | AC15: 28.7455
A16: det_pose | B16: 3 | C16: 1 | D16: 0 | E16: 1 | F16: 673 | G16: 23.7077 | H16: 34.6657 | L16: 673 | M16: 23.771 | N16: 34.5744 | O16: 19.7343 | P16: 8.67551 | Q16: 49.3111 | R16: 19.4657 | S16: 1366 | T16: 1965 | U16: 59.2554 | W16: 59.309 | X16: 5.05785 | Z16: 5.06832 | AA16: 28.7656 | AC16: 28.8393
A17: seg_pose | B17: 1 | C17: 0 | D17: 1 | E17: 1 | I17: 673 | J17: 29.259 | K17: 28.0739 | L17: 673 | M17: 27.7903 | N17: 29.3065 | O17: 17.8843 | P17: 8.59915 | Q17: 43.1909 | R17: 23.973 | S17: 1382 | T17: 4269 | V17: 87.038 | W17: 71.4728 | Y17: 6.28524 | Z17: 6.23199 | AB17: 35.5442 | AC17: 34.0223
A18: seg_pose | B18: 2 | C18: 0 | D18: 1 | E18: 1 | I18: 673 | J18: 29.2363 | K18: 28.4489 | L18: 673 | M18: 27.9965 | N18: 29.5801 | O18: 17.0642 | P18: 8.81434 | Q18: 44.3273 | R18: 23.6569 | S18: 1371 | T18: 4381 | V18: 95.541 | W18: 78.3074 | Y18: 5.82939 | Z18: 5.72993 | AB18: 35.0657 | AC18: 33.7264
A19: seg_pose | B19: 3 | C19: 0 | D19: 1 | E19: 1 | I19: 673 | J19: 29.2298 | K19: 28.226 | L19: 673 | M19: 27.6497 | N19: 29.5659 | O19: 18.213 | P19: 8.63384 | Q19: 43.4636 | R19: 23.8436 | S19: 1377 | T19: 4099 | V19: 78.16 | W19: 62.6122 | Y19: 6.11017 | Z19: 6.07243 | AB19: 35.34 | AC19: 33.7222
A20: det_seg_pose | B20: 1 | C20: 1 | D20: 1 | E20: 1 | F20: 673 | G20: 25.2073 | H20: 31.1828 | I20: 673 | J20: 26.4612 | K20: 31.0263 | L20: 673 | M20: 26.4333 | N20: 31.063 | O20: 24.9792 | P20: 8.02138 | Q20: 72.745 | R20: 21.6917 | S20: 3750 | T20: 6602 | U20: 58.4632 | V20: 58.978 | W20: 61.4171 | X20: 6.77642 | Y20: 5.68641 | Z20: 5.68125 | AA20: 31.9837 | AB20: 32.1476 | AC20: 32.1145
A21: det_seg_pose | B21: 2 | C21: 1 | D21: 1 | E21: 1 | F21: 673 | G21: 26.6817 | H21: 31.4102 | I21: 673 | J21: 26.7364 | K21: 31.2674 | L21: 673 | M21: 26.6694 | N21: 31.3834 | O21: 25.6736 | P21: 7.61379 | Q21: 73.36 | R21: 21.5245 | S21: 2191 | T21: 6978 | U21: 84.767 | V21: 70.5116 | W21: 66.5807 | X21: 5.06751 | Y21: 5.17781 | Z21: 5.10208 | AA21: 31.7492 | AB21: 31.9142 | AC21: 31.7715
A22: det_seg_pose | B22: 3 | C22: 1 | D22: 1 | E22: 1 | F22: 673 | G22: 26.795 | H22: 30.9191 | I22: 673 | J22: 26.8698 | K22: 30.7277 | L22: 673 | M22: 26.9739 | N22: 30.7601 | O22: 25.623 | P22: 8.12802 | Q22: 71.635 | R22: 21.9025 | S22: 2120 | T22: 4401 | U22: 63.7737 | V22: 59.808 | W22: 63.2241 | X22: 5.45966 | Y22: 5.60042 | Z22: 5.4543 | AA22: 32.2547 | AB22: 32.4702 | AC22: 32.4282

Sheet 참고_CLI_OFF_세트A
A1: label | B1: run_id | C1: use_det | D1: use_seg | E1: use_pose | F1: det_frame_count | G1: det_latency_ms | H1: det_fps | I1: seg_frame_count | J1: seg_latency_ms | K1: seg_fps | L1: pose_frame_count | M1: pose_latency_ms | N1: pose_fps | O1: cpu_percent | P1: mem_percent
A2: det | B2: 1 | C2: 1 | D2: 0 | E2: 0 | F2: 673 | G2: 17.9213 | H2: 42.1396 | O2: 12.5185 | P2: 8.58239
A3: det | B3: 2 | C3: 1 | D3: 0 | E3: 0 | F3: 673 | G3: 17.9383 | H3: 42.121 | O3: 12.3472 | P3: 8.31259
A4: det | B4: 3 | C4: 1 | D4: 0 | E4: 0 | F4: 673 | G4: 17.9627 | H4: 42.0176 | O4: 12.3372 | P4: 8.47077
A5: seg | B5: 1 | C5: 0 | D5: 1 | E5: 0 | I5: 673 | J5: 23.0127 | K5: 34.4379 | O5: 10.9623 | P5: 8.49514
A6: seg | B6: 2 | C6: 0 | D6: 1 | E6: 0 | I6: 673 | J6: 23.0039 | K6: 34.4383 | O6: 10.8675 | P6: 8.56333
A7: seg | B7: 3 | C7: 0 | D7: 1 | E7: 0 | I7: 673 | J7: 23.0221 | K7: 34.9525 | O7: 11.12 | P7: 8.53991
A8: pose | B8: 1 | C8: 0 | D8: 0 | E8: 1 | L8: 673 | M8: 17.9997 | N8: 41.9644 | O8: 12.1118 | P8: 8.38641
A9: pose | B9: 2 | C9: 0 | D9: 0 | E9: 1 | L9: 673 | M9: 18.0244 | N9: 41.8979 | O9: 12.8649 | P9: 8.55509
A10: pose | B10: 3 | C10: 0 | D10: 0 | E10: 1 | L10: 673 | M10: 18.0243 | N10: 41.9287 | O10: 13.1208 | P10: 8.52104
A11: det_seg | B11: 1 | C11: 1 | D11: 1 | E11: 0 | F11: 673 | G11: 25.3838 | H11: 31.8433 | I11: 673 | J11: 25.2945 | K11: 31.8535 | O11: 19.4242 | P11: 9.49554
A12: det_seg | B12: 2 | C12: 1 | D12: 1 | E12: 0 | F12: 673 | G12: 25.2828 | H12: 31.8847 | I12: 673 | J12: 25.3748 | K12: 31.7612 | O12: 18.7512 | P12: 9.36609
A13: det_seg | B13: 3 | C13: 1 | D13: 1 | E13: 0 | F13: 673 | G13: 25.2594 | H13: 31.9599 | I13: 673 | J13: 25.3707 | K13: 31.7969 | O13: 18.9053 | P13: 9.32224
A14: det_pose | B14: 1 | C14: 1 | D14: 0 | E14: 1 | F14: 673 | G14: 20.7206 | H14: 38.2135 | L14: 673 | M14: 20.7404 | N14: 38.1975 | O14: 21.0699 | P14: 9.62547
A15: det_pose | B15: 2 | C15: 1 | D15: 0 | E15: 1 | F15: 673 | G15: 20.8421 | H15: 37.9886 | L15: 673 | M15: 20.8415 | N15: 38.0266 | O15: 21.1317 | P15: 9.63588
A16: det_pose | B16: 3 | C16: 1 | D16: 0 | E16: 1 | F16: 673 | G16: 20.7036 | H16: 38.6395 | L16: 673 | M16: 20.6836 | N16: 38.6788 | O16: 21.016 | P16: 9.61024
A17: seg_pose | B17: 1 | C17: 0 | D17: 1 | E17: 1 | I17: 673 | J17: 25.4201 | K17: 31.6292 | L17: 673 | M17: 25.5475 | N17: 31.6216 | O17: 19.3682 | P17: 9.89405
A18: seg_pose | B18: 2 | C18: 0 | D18: 1 | E18: 1 | I18: 673 | J18: 25.4934 | K18: 31.5568 | L18: 673 | M18: 25.5569 | N18: 31.5929 | O18: 18.607 | P18: 9.00248
A19: seg_pose | B19: 3 | C19: 0 | D19: 1 | E19: 1 | I19: 673 | J19: 25.4882 | K19: 31.5493 | L19: 673 | M19: 25.6266 | N19: 31.5406 | O19: 19.2493 | P19: 9.21939
A20: det_seg_pose | B20: 1 | C20: 1 | D20: 1 | E20: 1 | F20: 673 | G20: 26.168 | H20: 31.8217 | I20: 673 | J20: 26.1008 | K20: 31.8025 | L20: 673 | M20: 26.1718 | N20: 31.7922 | O20: 26.5528 | P20: 10.0953
A21: det_seg_pose | B21: 2 | C21: 1 | D21: 1 | E21: 1 | F21: 673 | G21: 26.0847 | H21: 31.8744 | I21: 673 | J21: 25.9964 | K21: 31.8522 | L21: 673 | M21: 26.0407 | N21: 31.8874 | O21: 26.0051 | P21: 10.3884
A22: det_seg_pose | B22: 3 | C22: 1 | D22: 1 | E22: 1 | F22: 673 | G22: 26.1236 | H22: 31.4962 | I22: 673 | J22: 25.9718 | K22: 31.5231 | L22: 673 | M22: 26.0473 | N22: 31.5125 | O22: 26.7365 | P22: 10.1705

Sheet 조건별_비교
A1: 조건별 평균 비교 — CLI OFF(기준) vs CLI ON
A2: 차이율(%) = (CLI ON - CLI OFF) / CLI OFF. 지연시간·CPU·MEM은 +가 증가(악화), FPS는 +가 증가(개선). n=3런/조건.
A4: 조건 | B4: 지표 | C4: 모델 | D4: 원본 열 (CLI OFF) | E4: 원본 열 (CLI ON) | F4: CLI OFF 평균 | G4: CLI OFF 표준편차 | H4: CLI ON 평균 | I4: CLI ON 표준편차 | J4: 차이 (ON-OFF) | K4: 차이율 (%) | L4: 노이즈 판정
A5: det | B5: 지연시간(ms) | C5: det | D5: det_avg_latency_ms | E5: det_latency_ms | F5: =AVERAGE(원본_CLI_OFF!G2:G4) -> 17.8358 | G5: =STDEV(원본_CLI_OFF!G2:G4) -> 0.0053507009 | H5: =AVERAGE(원본_CLI_ON!G2:G4) -> 19.169867 | I5: =STDEV(원본_CLI_ON!G2:G4) -> 0.14788287 | J5: =H5-F5 -> 1.3340667 | K5: =IF(F5=0,"",J5/F5) -> 0.074797131 | L5: =IF(ABS(J5)>(G5+I5),"노이즈 초과","노이즈 수준") -> 노이즈 초과
A6: det | B6: FPS | C6: det | D6: det_fps | E6: avg_fps_det | F6: =AVERAGE(원본_CLI_OFF!H2:H4) -> 42.3454 | G6: =STDEV(원본_CLI_OFF!H2:H4) -> 0.041019386 | H6: =AVERAGE(원본_CLI_ON!H2:H4) -> 39.915967 | I6: =STDEV(원본_CLI_ON!H2:H4) -> 0.22901551 | J6: =H6-F6 -> -2.4294333 | K6: =IF(F6=0,"",J6/F6) -> -0.057371836 | L6: =IF(ABS(J6)>(G6+I6),"노이즈 초과","노이즈 수준") -> 노이즈 초과
A7: det | B7: CPU(%) | C7: - | D7: cpu_percent | E7: cpu_percent | F7: =AVERAGE(원본_CLI_OFF!O2:O4) -> 12.7268 | G7: =STDEV(원본_CLI_OFF!O2:O4) -> 0.19013669 | H7: =AVERAGE(원본_CLI_ON!O2:O4) -> 12.604033 | I7: =STDEV(원본_CLI_ON!O2:O4) -> 0.48222767 | J7: =H7-F7 -> -0.12276667 | K7: =IF(F7=0,"",J7/F7) -> -0.0096463107 | L7: =IF(ABS(J7)>(G7+I7),"노이즈 초과","노이즈 수준") -> 노이즈 수준
A8: det | B8: MEM(%) | C8: - | D8: mem_percent | E8: mem_percent | F8: =AVERAGE(원본_CLI_OFF!P2:P4) -> 6.80632 | G8: =STDEV(원본_CLI_OFF!P2:P4) -> 0.078391924 | H8: =AVERAGE(원본_CLI_ON!P2:P4) -> 7.93998 | I8: =STDEV(원본_CLI_ON!P2:P4) -> 0.1078476 | J8: =H8-F8 -> 1.13366 | K8: =IF(F8=0,"",J8/F8) -> 0.1665599 | L8: =IF(ABS(J8)>(G8+I8),"노이즈 초과","노이즈 수준") -> 노이즈 초과
A9: seg | B9: 지연시간(ms) | C9: seg | D9: seg_avg_latency_ms | E9: seg_latency_ms | F9: =AVERAGE(원본_CLI_OFF!J5:J7) -> 22.8428 | G9: =STDEV(원본_CLI_OFF!J5:J7) -> 0.049768665 | H9: =AVERAGE(원본_CLI_ON!J5:J7) -> 24.697867 | I9: =STDEV(원본_CLI_ON!J5:J7) -> 0.11300267 | J9: =H9-F9 -> 1.8550667 | K9: =IF(F9=0,"",J9/F9) -> 0.081210126 | L9: =IF(ABS(J9)>(G9+I9),"노이즈 초과","노이즈 수준") -> 노이즈 초과
A10: seg | B10: FPS | C10: seg | D10: seg_fps | E10: avg_fps_seg | F10: =AVERAGE(원본_CLI_OFF!K5:K7) -> 34.6877 | G10: =STDEV(원본_CLI_OFF!K5:K7) -> 0.066257754 | H10: =AVERAGE(원본_CLI_ON!K5:K7) -> 32.656067 | I10: =STDEV(원본_CLI_ON!K5:K7) -> 0.19440572 | J10: =H10-F10 -> -2.0316333 | K10: =IF(F10=0,"",J10/F10) -> -0.058569272 | L10: =IF(ABS(J10)>(G10+I10),"노이즈 초과","노이즈 수준") -> 노이즈 초과
A11: seg | B11: CPU(%) | C11: - | D11: cpu_percent | E11: cpu_percent | F11: =AVERAGE(원본_CLI_OFF!O5:O7) -> 10.9258 | G11: =STDEV(원본_CLI_OFF!O5:O7) -> 0.25945603 | H11: =AVERAGE(원본_CLI_ON!O5:O7) -> 10.490767 | I11: =STDEV(원본_CLI_ON!O5:O7) -> 0.38430406 | J11: =H11-F11 -> -0.43503333 | K11: =IF(F11=0,"",J11/F11) -> -0.039817069 | L11: =IF(ABS(J11)>(G11+I11),"노이즈 초과","노이즈 수준") -> 노이즈 수준
A12: seg | B12: MEM(%) | C12: - | D12: mem_percent | E12: mem_percent | F12: =AVERAGE(원본_CLI_OFF!P5:P7) -> 6.9555533 | G12: =STDEV(원본_CLI_OFF!P5:P7) -> 0.15953682 | H12: =AVERAGE(원본_CLI_ON!P5:P7) -> 8.1022467 | I12: =STDEV(원본_CLI_ON!P5:P7) -> 0.052295933 | J12: =H12-F12 -> 1.1466933 | K12: =IF(F12=0,"",J12/F12) -> 0.16486012 | L12: =IF(ABS(J12)>(G12+I12),"노이즈 초과","노이즈 수준") -> 노이즈 초과
A13: pose | B13: 지연시간(ms) | C13: pose | D13: pose_avg_latency_ms | E13: pose_latency_ms | F13: =AVERAGE(원본_CLI_OFF!M8:M10) -> 17.817933 | G13: =STDEV(원본_CLI_OFF!M8:M10) -> 0.0096344867 | H13: =AVERAGE(원본_CLI_ON!M8:M10) -> 19.670167 | I13: =STDEV(원본_CLI_ON!M8:M10) -> 0.23491752 | J13: =H13-F13 -> 1.8522333 | K13: =IF(F13=0,"",J13/F13) -> 0.10395332 | L13: =IF(ABS(J13)>(G13+I13),"노이즈 초과","노이즈 수준") -> 노이즈 초과
A14: pose | B14: FPS | C14: pose | D14: pose_fps | E14: avg_fps_pose | F14: =AVERAGE(원본_CLI_OFF!N8:N10) -> 42.374167 | G14: =STDEV(원본_CLI_OFF!N8:N10) -> 0.032939692 | H14: =AVERAGE(원본_CLI_ON!N8:N10) -> 39.1117 | I14: =STDEV(원본_CLI_ON!N8:N10) -> 0.34626864 | J14: =H14-F14 -> -3.2624667 | K14: =IF(F14=0,"",J14/F14) -> -0.076991878 | L14: =IF(ABS(J14)>(G14+I14),"노이즈 초과","노이즈 수준") -> 노이즈 초과
A15: pose | B15: CPU(%) | C15: - | D15: cpu_percent | E15: cpu_percent | F15: =AVERAGE(원본_CLI_OFF!O8:O10) -> 12.725867 | G15: =STDEV(원본_CLI_OFF!O8:O10) -> 0.33237166 | H15: =AVERAGE(원본_CLI_ON!O8:O10) -> 12.3272 | I15: =STDEV(원본_CLI_ON!O8:O10) -> 0.30556171 | J15: =H15-F15 -> -0.39866667 | K15: =IF(F15=0,"",J15/F15) -> -0.03132727 | L15: =IF(ABS(J15)>(G15+I15),"노이즈 초과","노이즈 수준") -> 노이즈 수준
A16: pose | B16: MEM(%) | C16: - | D16: mem_percent | E16: mem_percent | F16: =AVERAGE(원본_CLI_OFF!P8:P10) -> 6.97832 | G16: =STDEV(원본_CLI_OFF!P8:P10) -> 0.040128231 | H16: =AVERAGE(원본_CLI_ON!P8:P10) -> 7.9418033 | I16: =STDEV(원본_CLI_ON!P8:P10) -> 0.14816694 | J16: =H16-F16 -> 0.96348333 | K16: =IF(F16=0,"",J16/F16) -> 0.13806809 | L16: =IF(ABS(J16)>(G16+I16),"노이즈 초과","노이즈 수준") -> 노이즈 초과
A17: det_seg | B17: 지연시간(ms) | C17: det | D17: det_avg_latency_ms | E17: det_latency_ms | F17: =AVERAGE(원본_CLI_OFF!G11:G13) -> 25.1568 | G17: =STDEV(원본_CLI_OFF!G11:G13) -> 0.0351 | H17: =AVERAGE(원본_CLI_ON!G11:G13) -> 26.876767 | I17: =STDEV(원본_CLI_ON!G11:G13) -> 0.40276854 | J17: =H17-F17 -> 1.7199667 | K17: =IF(F17=0,"",J17/F17) -> 0.068369851 | L17: =IF(ABS(J17)>(G17+I17),"노이즈 초과","노이즈 수준") -> 노이즈 초과
A18: det_seg | B18: 지연시간(ms) | C18: seg | D18: seg_avg_latency_ms | E18: seg_latency_ms | F18: =AVERAGE(원본_CLI_OFF!J11:J13) -> 25.160733 | G18: =STDEV(원본_CLI_OFF!J11:J13) -> 0.066023127 | H18: =AVERAGE(원본_CLI_ON!J11:J13) -> 28.0306 | I18: =STDEV(원본_CLI_ON!J11:J13) -> 0.12312754 | J18: =H18-F18 -> 2.8698667 | K18: =IF(F18=0,"",J18/F18) -> 0.11406133 | L18: =IF(ABS(J18)>(G18+I18),"노이즈 초과","노이즈 수준") -> 노이즈 초과
A19: det_seg | B19: FPS | C19: det | D19: det_fps | E19: avg_fps_det | F19: =AVERAGE(원본_CLI_OFF!H11:H13) -> 32.0327 | G19: =STDEV(원본_CLI_OFF!H11:H13) -> 0.15344123 | H19: =AVERAGE(원본_CLI_ON!H11:H13) -> 30.2846 | I19: =STDEV(원본_CLI_ON!H11:H13) -> 0.36787956 | J19: =H19-F19 -> -1.7481 | K19: =IF(F19=0,"",J19/F19) -> -0.054572359 | L19: =IF(ABS(J19)>(G19+I19),"노이즈 초과","노이즈 수준") -> 노이즈 초과
A20: det_seg | B20: FPS | C20: seg | D20: seg_fps | E20: avg_fps_seg | F20: =AVERAGE(원본_CLI_OFF!K11:K13) -> 31.985867 | G20: =STDEV(원본_CLI_OFF!K11:K13) -> 0.2480063 | H20: =AVERAGE(원본_CLI_ON!K11:K13) -> 29.242467 | I20: =STDEV(원본_CLI_ON!K11:K13) -> 0.1193014 | J20: =H20-F20 -> -2.7434 | K20: =IF(F20=0,"",J20/F20) -> -0.085769131 | L20: =IF(ABS(J20)>(G20+I20),"노이즈 초과","노이즈 수준") -> 노이즈 초과
A21: det_seg | B21: CPU(%) | C21: - | D21: cpu_percent | E21: cpu_percent | F21: =AVERAGE(원본_CLI_OFF!O11:O13) -> 19.154233 | G21: =STDEV(원본_CLI_OFF!O11:O13) -> 0.20713267 | H21: =AVERAGE(원본_CLI_ON!O11:O13) -> 18.0408 | I21: =STDEV(원본_CLI_ON!O11:O13) -> 0.19835546 | J21: =H21-F21 -> -1.1134333 | K21: =IF(F21=0,"",J21/F21) -> -0.058129883 | L21: =IF(ABS(J21)>(G21+I21),"노이즈 초과","노이즈 수준") -> 노이즈 초과
A22: det_seg | B22: MEM(%) | C22: - | D22: mem_percent | E22: mem_percent | F22: =AVERAGE(원본_CLI_OFF!P11:P13) -> 7.863 | G22: =STDEV(원본_CLI_OFF!P11:P13) -> 0.15574833 | H22: =AVERAGE(원본_CLI_ON!P11:P13) -> 8.4897833 | I22: =STDEV(원본_CLI_ON!P11:P13) -> 0.230276 | J22: =H22-F22 -> 0.62678333 | K22: =IF(F22=0,"",J22/F22) -> 0.079713002 | L22: =IF(ABS(J22)>(G22+I22),"노이즈 초과","노이즈 수준") -> 노이즈 초과
A23: det_pose | B23: 지연시간(ms) | C23: det | D23: det_avg_latency_ms | E23: det_latency_ms | F23: =AVERAGE(원본_CLI_OFF!G14:G16) -> 20.723933 | G23: =STDEV(원본_CLI_OFF!G14:G16) -> 0.066359727 | H23: =AVERAGE(원본_CLI_ON!G14:G16) -> 23.564833 | I23: =STDEV(원본_CLI_ON!G14:G16) -> 0.18378513 | J23: =H23-F23 -> 2.8409 | K23: =IF(F23=0,"",J23/F23) -> 0.13708305 | L23: =IF(ABS(J23)>(G23+I23),"노이즈 초과","노이즈 수준") -> 노이즈 초과
A24: det_pose | B24: 지연시간(ms) | C24: pose | D24: pose_avg_latency_ms | E24: pose_latency_ms | F24: =AVERAGE(원본_CLI_OFF!M14:M16) -> 20.745 | G24: =STDEV(원본_CLI_OFF!M14:M16) -> 0.084179154 | H24: =AVERAGE(원본_CLI_ON!M14:M16) -> 23.6841 | I24: =STDEV(원본_CLI_ON!M14:M16) -> 0.087557238 | J24: =H24-F24 -> 2.9391 | K24: =IF(F24=0,"",J24/F24) -> 0.14167751 | L24: =IF(ABS(J24)>(G24+I24),"노이즈 초과","노이즈 수준") -> 노이즈 초과
A25: det_pose | B25: FPS | C25: det | D25: det_fps | E25: avg_fps_det | F25: =AVERAGE(원본_CLI_OFF!H14:H16) -> 38.236 | G25: =STDEV(원본_CLI_OFF!H14:H16) -> 0.7220284 | H25: =AVERAGE(원본_CLI_ON!H14:H16) -> 34.523467 | I25: =STDEV(원본_CLI_ON!H14:H16) -> 0.3406035 | J25: =H25-F25 -> -3.7125333 | K25: =IF(F25=0,"",J25/F25) -> -0.097095233 | L25: =IF(ABS(J25)>(G25+I25),"노이즈 초과","노이즈 수준") -> 노이즈 초과
A26: det_pose | B26: FPS | C26: pose | D26: pose_fps | E26: avg_fps_pose | F26: =AVERAGE(원본_CLI_OFF!N14:N16) -> 38.2378 | G26: =STDEV(원본_CLI_OFF!N14:N16) -> 0.75462614 | H26: =AVERAGE(원본_CLI_ON!N14:N16) -> 34.3902 | I26: =STDEV(원본_CLI_ON!N14:N16) -> 0.43193656 | J26: =H26-F26 -> -3.8476 | K26: =IF(F26=0,"",J26/F26) -> -0.10062294 | L26: =IF(ABS(J26)>(G26+I26),"노이즈 초과","노이즈 수준") -> 노이즈 초과
A27: det_pose | B27: CPU(%) | C27: - | D27: cpu_percent | E27: cpu_percent | F27: =AVERAGE(원본_CLI_OFF!O14:O16) -> 21.226433 | G27: =STDEV(원본_CLI_OFF!O14:O16) -> 0.63034082 | H27: =AVERAGE(원본_CLI_ON!O14:O16) -> 19.734933 | I27: =STDEV(원본_CLI_ON!O14:O16) -> 0.59065025 | J27: =H27-F27 -> -1.4915 | K27: =IF(F27=0,"",J27/F27) -> -0.070266162 | L27: =IF(ABS(J27)>(G27+I27),"노이즈 초과","노이즈 수준") -> 노이즈 초과
A28: det_pose | B28: MEM(%) | C28: - | D28: mem_percent | E28: mem_percent | F28: =AVERAGE(원본_CLI_OFF!P14:P16) -> 7.81261 | G28: =STDEV(원본_CLI_OFF!P14:P16) -> 0.14196432 | H28: =AVERAGE(원본_CLI_ON!P14:P16) -> 8.5524367 | I28: =STDEV(원본_CLI_ON!P14:P16) -> 0.21233842 | J28: =H28-F28 -> 0.73982667 | K28: =IF(F28=0,"",J28/F28) -> 0.09469648 | L28: =IF(ABS(J28)>(G28+I28),"노이즈 초과","노이즈 수준") -> 노이즈 초과
A29: seg_pose | B29: 지연시간(ms) | C29: seg | D29: seg_avg_latency_ms | E29: seg_latency_ms | F29: =AVERAGE(원본_CLI_OFF!J17:J19) -> 25.523667 | G29: =STDEV(원본_CLI_OFF!J17:J19) -> 0.061507913 | H29: =AVERAGE(원본_CLI_ON!J17:J19) -> 29.2417 | I29: =STDEV(원본_CLI_ON!J17:J19) -> 0.015330688 | J29: =H29-F29 -> 3.7180333 | K29: =IF(F29=0,"",J29/F29) -> 0.14567003 | L29: =IF(ABS(J29)>(G29+I29),"노이즈 초과","노이즈 수준") -> 노이즈 초과
A30: seg_pose | B30: 지연시간(ms) | C30: pose | D30: pose_avg_latency_ms | E30: pose_latency_ms | F30: =AVERAGE(원본_CLI_OFF!M17:M19) -> 25.564967 | G30: =STDEV(원본_CLI_OFF!M17:M19) -> 0.04308391 | H30: =AVERAGE(원본_CLI_ON!M17:M19) -> 27.812167 | I30: =STDEV(원본_CLI_ON!M17:M19) -> 0.174431 | J30: =H30-F30 -> 2.2472 | K30: =IF(F30=0,"",J30/F30) -> 0.087901542 | L30: =IF(ABS(J30)>(G30+I30),"노이즈 초과","노이즈 수준") -> 노이즈 초과
A31: seg_pose | B31: FPS | C31: seg | D31: seg_fps | E31: avg_fps_seg | F31: =AVERAGE(원본_CLI_OFF!K17:K19) -> 31.583133 | G31: =STDEV(원본_CLI_OFF!K17:K19) -> 0.050185091 | H31: =AVERAGE(원본_CLI_ON!K17:K19) -> 28.2496 | I31: =STDEV(원본_CLI_ON!K17:K19) -> 0.18861063 | J31: =H31-F31 -> -3.3335333 | K31: =IF(F31=0,"",J31/F31) -> -0.1055479 | L31: =IF(ABS(J31)>(G31+I31),"노이즈 초과","노이즈 수준") -> 노이즈 초과
A32: seg_pose | B32: FPS | C32: pose | D32: pose_fps | E32: avg_fps_pose | F32: =AVERAGE(원본_CLI_OFF!N17:N19) -> 31.645 | G32: =STDEV(원본_CLI_OFF!N17:N19) -> 0.052707115 | H32: =AVERAGE(원본_CLI_ON!N17:N19) -> 29.484167 | I32: =STDEV(원본_CLI_ON!N17:N19) -> 0.15402757 | J32: =H32-F32 -> -2.1608333 | K32: =IF(F32=0,"",J32/F32) -> -0.068283562 | L32: =IF(ABS(J32)>(G32+I32),"노이즈 초과","노이즈 수준") -> 노이즈 초과
A33: seg_pose | B33: CPU(%) | C33: - | D33: cpu_percent | E33: cpu_percent | F33: =AVERAGE(원본_CLI_OFF!O17:O19) -> 19.048767 | G33: =STDEV(원본_CLI_OFF!O17:O19) -> 0.2748287 | H33: =AVERAGE(원본_CLI_ON!O17:O19) -> 17.7205 | I33: =STDEV(원본_CLI_ON!O17:O19) -> 0.59165716 | J33: =H33-F33 -> -1.3282667 | K33: =IF(F33=0,"",J33/F33) -> -0.069729799 | L33: =IF(ABS(J33)>(G33+I33),"노이즈 초과","노이즈 수준") -> 노이즈 초과
A34: seg_pose | B34: MEM(%) | C34: - | D34: mem_percent | E34: mem_percent | F34: =AVERAGE(원본_CLI_OFF!P17:P19) -> 8.1872 | G34: =STDEV(원본_CLI_OFF!P17:P19) -> 0.28604928 | H34: =AVERAGE(원본_CLI_ON!P17:P19) -> 8.6824433 | I34: =STDEV(원본_CLI_ON!P17:P19) -> 0.11553526 | J34: =H34-F34 -> 0.49524333 | K34: =IF(F34=0,"",J34/F34) -> 0.060489952 | L34: =IF(ABS(J34)>(G34+I34),"노이즈 초과","노이즈 수준") -> 노이즈 초과
A35: det_seg_pose | B35: 지연시간(ms) | C35: det | D35: det_avg_latency_ms | E35: det_latency_ms | F35: =AVERAGE(원본_CLI_OFF!G20:G22) -> 25.936333 | G35: =STDEV(원본_CLI_OFF!G20:G22) -> 0.10295496 | H35: =AVERAGE(원본_CLI_ON!G20:G22) -> 26.228 | I35: =STDEV(원본_CLI_ON!G20:G22) -> 0.88576554 | J35: =H35-F35 -> 0.29166667 | K35: =IF(F35=0,"",J35/F35) -> 0.011245486 | L35: =IF(ABS(J35)>(G35+I35),"노이즈 초과","노이즈 수준") -> 노이즈 수준
A36: det_seg_pose | B36: 지연시간(ms) | C36: seg | D36: seg_avg_latency_ms | E36: seg_latency_ms | F36: =AVERAGE(원본_CLI_OFF!J20:J22) -> 25.818167 | G36: =STDEV(원본_CLI_OFF!J20:J22) -> 0.15020907 | H36: =AVERAGE(원본_CLI_ON!J20:J22) -> 26.689133 | I36: =STDEV(원본_CLI_ON!J20:J22) -> 0.20836049 | J36: =H36-F36 -> 0.87096667 | K36: =IF(F36=0,"",J36/F36) -> 0.033734644 | L36: =IF(ABS(J36)>(G36+I36),"노이즈 초과","노이즈 수준") -> 노이즈 초과
A37: det_seg_pose | B37: 지연시간(ms) | C37: pose | D37: pose_avg_latency_ms | E37: pose_latency_ms | F37: =AVERAGE(원본_CLI_OFF!M20:M22) -> 25.860033 | G37: =STDEV(원본_CLI_OFF!M20:M22) -> 0.066412223 | H37: =AVERAGE(원본_CLI_ON!M20:M22) -> 26.6922 | I37: =STDEV(원본_CLI_ON!M20:M22) -> 0.27102024 | J37: =H37-F37 -> 0.83216667 | K37: =IF(F37=0,"",J37/F37) -> 0.032179644 | L37: =IF(ABS(J37)>(G37+I37),"노이즈 초과","노이즈 수준") -> 노이즈 초과
A38: det_seg_pose | B38: FPS | C38: det | D38: det_fps | E38: avg_fps_det | F38: =AVERAGE(원본_CLI_OFF!H20:H22) -> 31.712367 | G38: =STDEV(원본_CLI_OFF!H20:H22) -> 0.35330206 | H38: =AVERAGE(원본_CLI_ON!H20:H22) -> 31.1707 | I38: =STDEV(원본_CLI_ON!H20:H22) -> 0.24577349 | J38: =H38-F38 -> -0.54166667 | K38: =IF(F38=0,"",J38/F38) -> -0.017080613 | L38: =IF(ABS(J38)>(G38+I38),"노이즈 초과","노이즈 수준") -> 노이즈 수준
A39: det_seg_pose | B39: FPS | C39: seg | D39: seg_fps | E39: avg_fps_seg | F39: =AVERAGE(원본_CLI_OFF!K20:K22) -> 31.702267 | G39: =STDEV(원본_CLI_OFF!K20:K22) -> 0.35398724 | H39: =AVERAGE(원본_CLI_ON!K20:K22) -> 31.007133 | I39: =STDEV(원본_CLI_ON!K20:K22) -> 0.27036003 | J39: =H39-F39 -> -0.69513333 | K39: =IF(F39=0,"",J39/F39) -> -0.021926928 | L39: =IF(ABS(J39)>(G39+I39),"노이즈 초과","노이즈 수준") -> 노이즈 초과
A40: det_seg_pose | B40: FPS | C40: pose | D40: pose_fps | E40: avg_fps_pose | F40: =AVERAGE(원본_CLI_OFF!N20:N22) -> 31.739767 | G40: =STDEV(원본_CLI_OFF!N20:N22) -> 0.41248911 | H40: =AVERAGE(원본_CLI_ON!N20:N22) -> 31.068833 | I40: =STDEV(원본_CLI_ON!N20:N22) -> 0.31169094 | J40: =H40-F40 -> -0.67093333 | K40: =IF(F40=0,"",J40/F40) -> -0.021138572 | L40: =IF(ABS(J40)>(G40+I40),"노이즈 초과","노이즈 수준") -> 노이즈 수준
A41: det_seg_pose | B41: CPU(%) | C41: - | D41: cpu_percent | E41: cpu_percent | F41: =AVERAGE(원본_CLI_OFF!O20:O22) -> 26.948033 | G41: =STDEV(원본_CLI_OFF!O20:O22) -> 1.3156667 | H41: =AVERAGE(원본_CLI_ON!O20:O22) -> 25.425267 | I41: =STDEV(원본_CLI_ON!O20:O22) -> 0.38713266 | J41: =H41-F41 -> -1.5227667 | K41: =IF(F41=0,"",J41/F41) -> -0.056507525 | L41: =IF(ABS(J41)>(G41+I41),"노이즈 초과","노이즈 수준") -> 노이즈 수준
...

Sheet 그래프_데이터
A1: 평균 지연시간 (ms)
A2: 구분 | B2: CLI OFF | C2: CLI ON | D2: 차이율 (%)
A3: det [det] | B3: =조건별_비교!F5 -> 17.8358 | C3: =조건별_비교!H5 -> 19.169867 | D3: =조건별_비교!K5 -> 0.074797131
A4: seg [seg] | B4: =조건별_비교!F9 -> 22.8428 | C4: =조건별_비교!H9 -> 24.697867 | D4: =조건별_비교!K9 -> 0.081210126
A5: pose [pose] | B5: =조건별_비교!F13 -> 17.817933 | C5: =조건별_비교!H13 -> 19.670167 | D5: =조건별_비교!K13 -> 0.10395332
A6: det_seg [det] | B6: =조건별_비교!F17 -> 25.1568 | C6: =조건별_비교!H17 -> 26.876767 | D6: =조건별_비교!K17 -> 0.068369851
A7: det_seg [seg] | B7: =조건별_비교!F18 -> 25.160733 | C7: =조건별_비교!H18 -> 28.0306 | D7: =조건별_비교!K18 -> 0.11406133
A8: det_pose [det] | B8: =조건별_비교!F23 -> 20.723933 | C8: =조건별_비교!H23 -> 23.564833 | D8: =조건별_비교!K23 -> 0.13708305
A9: det_pose [pose] | B9: =조건별_비교!F24 -> 20.745 | C9: =조건별_비교!H24 -> 23.6841 | D9: =조건별_비교!K24 -> 0.14167751
A10: seg_pose [seg] | B10: =조건별_비교!F29 -> 25.523667 | C10: =조건별_비교!H29 -> 29.2417 | D10: =조건별_비교!K29 -> 0.14567003
A11: seg_pose [pose] | B11: =조건별_비교!F30 -> 25.564967 | C11: =조건별_비교!H30 -> 27.812167 | D11: =조건별_비교!K30 -> 0.087901542
A12: det_seg_pose [det] | B12: =조건별_비교!F35 -> 25.936333 | C12: =조건별_비교!H35 -> 26.228 | D12: =조건별_비교!K35 -> 0.011245486
A13: det_seg_pose [seg] | B13: =조건별_비교!F36 -> 25.818167 | C13: =조건별_비교!H36 -> 26.689133 | D13: =조건별_비교!K36 -> 0.033734644
A14: det_seg_pose [pose] | B14: =조건별_비교!F37 -> 25.860033 | C14: =조건별_비교!H37 -> 26.6922 | D14: =조건별_비교!K37 -> 0.032179644
A17: 평균 FPS
A18: 구분 | B18: CLI OFF | C18: CLI ON | D18: 차이율 (%)
A19: det [det] | B19: =조건별_비교!F6 -> 42.3454 | C19: =조건별_비교!H6 -> 39.915967 | D19: =조건별_비교!K6 -> -0.057371836
A20: seg [seg] | B20: =조건별_비교!F10 -> 34.6877 | C20: =조건별_비교!H10 -> 32.656067 | D20: =조건별_비교!K10 -> -0.058569272
A21: pose [pose] | B21: =조건별_비교!F14 -> 42.374167 | C21: =조건별_비교!H14 -> 39.1117 | D21: =조건별_비교!K14 -> -0.076991878
A22: det_seg [det] | B22: =조건별_비교!F19 -> 32.0327 | C22: =조건별_비교!H19 -> 30.2846 | D22: =조건별_비교!K19 -> -0.054572359
A23: det_seg [seg] | B23: =조건별_비교!F20 -> 31.985867 | C23: =조건별_비교!H20 -> 29.242467 | D23: =조건별_비교!K20 -> -0.085769131
A24: det_pose [det] | B24: =조건별_비교!F25 -> 38.236 | C24: =조건별_비교!H25 -> 34.523467 | D24: =조건별_비교!K25 -> -0.097095233
A25: det_pose [pose] | B25: =조건별_비교!F26 -> 38.2378 | C25: =조건별_비교!H26 -> 34.3902 | D25: =조건별_비교!K26 -> -0.10062294
A26: seg_pose [seg] | B26: =조건별_비교!F31 -> 31.583133 | C26: =조건별_비교!H31 -> 28.2496 | D26: =조건별_비교!K31 -> -0.1055479
A27: seg_pose [pose] | B27: =조건별_비교!F32 -> 31.645 | C27: =조건별_비교!H32 -> 29.484167 | D27: =조건별_비교!K32 -> -0.068283562
A28: det_seg_pose [det] | B28: =조건별_비교!F38 -> 31.712367 | C28: =조건별_비교!H38 -> 31.1707 | D28: =조건별_비교!K38 -> -0.017080613
A29: det_seg_pose [seg] | B29: =조건별_비교!F39 -> 31.702267 | C29: =조건별_비교!H39 -> 31.007133 | D29: =조건별_비교!K39 -> -0.021926928
A30: det_seg_pose [pose] | B30: =조건별_비교!F40 -> 31.739767 | C30: =조건별_비교!H40 -> 31.068833 | D30: =조건별_비교!K40 -> -0.021138572
A33: CPU 사용률 (%)
A34: 구분 | B34: CLI OFF | C34: CLI ON | D34: 차이율 (%)
A35: det | B35: =조건별_비교!F7 -> 12.7268 | C35: =조건별_비교!H7 -> 12.604033 | D35: =조건별_비교!K7 -> -0.0096463107
A36: seg | B36: =조건별_비교!F11 -> 10.9258 | C36: =조건별_비교!H11 -> 10.490767 | D36: =조건별_비교!K11 -> -0.039817069
A37: pose | B37: =조건별_비교!F15 -> 12.725867 | C37: =조건별_비교!H15 -> 12.3272 | D37: =조건별_비교!K15 -> -0.03132727
A38: det_seg | B38: =조건별_비교!F21 -> 19.154233 | C38: =조건별_비교!H21 -> 18.0408 | D38: =조건별_비교!K21 -> -0.058129883
A39: det_pose | B39: =조건별_비교!F27 -> 21.226433 | C39: =조건별_비교!H27 -> 19.734933 | D39: =조건별_비교!K27 -> -0.070266162
A40: seg_pose | B40: =조건별_비교!F33 -> 19.048767 | C40: =조건별_비교!H33 -> 17.7205 | D40: =조건별_비교!K33 -> -0.069729799
A41: det_seg_pose | B41: =조건별_비교!F41 -> 26.948033 | C41: =조건별_비교!H41 -> 25.425267 | D41: =조건별_비교!K41 -> -0.056507525
A44: MEM 사용률 (%)
A45: 구분 | B45: CLI OFF | C45: CLI ON | D45: 차이율 (%)
A46: det | B46: =조건별_비교!F8 -> 6.80632 | C46: =조건별_비교!H8 -> 7.93998 | D46: =조건별_비교!K8 -> 0.1665599
...

Sheet 그래프
A1: CLI 계측 유무에 따른 추론 성능 비교
A2: 막대 2개 = 같은 조건의 CLI OFF / CLI ON. 아래쪽 차트는 조건별 변화율(%)이다. 데이터는 "그래프_데이터" 시트, 계산은 "조건별_비교" 시트.

Sheet CLI전용지표
A1: CLI ON 실험에만 존재하는 열 (조건별 3런 평균) — 비교 대상 아님, 참고용
A2: 8L에서 HRTT가 주던 값을 H10에서는 hailortcli monitor + 호스트 실측으로 대체한 열이다. CLI OFF 실험에는 해당 열 자체가 없어 % 차이를 계산할 수 없다.
A4: 조건 | B4: npu_percent | C4: run_time_s | D4: voluntary_ctx_switches | E4: nonvoluntary_ctx_switches | F4: max_latency_det | G4: max_latency_seg | H4: max_latency_pose | I4: avg_preprocess_ms_det | J4: avg_preprocess_ms_seg | K4: avg_preprocess_ms_pose | L4: total_time_ms_nopp_det | M4: total_time_ms_nopp_seg | N4: total_time_ms_nopp_pose
A5: det | B5: =IF(COUNT(원본_CLI_ON!Q2:Q4)=0,"",AVERAGE(원본_CLI_ON!Q2:Q4)) -> 23.256267 | C5: =IF(COUNT(원본_CLI_ON!R2:R4)=0,"",AVERAGE(원본_CLI_ON!R2:R4)) -> 16.861133 | D5: =IF(COUNT(원본_CLI_ON!S2:S4)=0,"",AVERAGE(원본_CLI_ON!S2:S4)) -> 674.33333 | E5: =IF(COUNT(원본_CLI_ON!T2:T4)=0,"",AVERAGE(원본_CLI_ON!T2:T4)) -> 215.33333 | F5: =IF(COUNT(원본_CLI_ON!U2:U4)=0,"",AVERAGE(원본_CLI_ON!U2:U4)) -> 45.936 | G5: =IF(COUNT(원본_CLI_ON!V2:V4)=0,"",AVERAGE(원본_CLI_ON!V2:V4)) | H5: =IF(COUNT(원본_CLI_ON!W2:W4)=0,"",AVERAGE(원본_CLI_ON!W2:W4)) | I5: =IF(COUNT(원본_CLI_ON!X2:X4)=0,"",AVERAGE(원본_CLI_ON!X2:X4)) -> 5.8072567 | ... N5: =IF(COUNT(원본_CLI_ON!AC2:AC4)=0,"",AVERAGE(원본_CLI_ON!AC2:AC4))
A6: seg | B6: =IF(COUNT(원본_CLI_ON!Q5:Q7)=0,"",AVERAGE(원본_CLI_ON!Q5:Q7)) -> 22.9842 | C6: =IF(COUNT(원본_CLI_ON!R5:R7)=0,"",AVERAGE(원본_CLI_ON!R5:R7)) -> 20.609567 | D6: =IF(COUNT(원본_CLI_ON!S5:S7)=0,"",AVERAGE(원본_CLI_ON!S5:S7)) -> 675 | E6: =IF(COUNT(원본_CLI_ON!T5:T7)=0,"",AVERAGE(원본_CLI_ON!T5:T7)) -> 224 | F6: =IF(COUNT(원본_CLI_ON!U5:U7)=0,"",AVERAGE(원본_CLI_ON!U5:U7)) | G6: =IF(COUNT(원본_CLI_ON!V5:V7)=0,"",AVERAGE(원본_CLI_ON!V5:V7)) -> 57.224333 | H6: =IF(COUNT(원본_CLI_ON!W5:W7)=0,"",AVERAGE(원본_CLI_ON!W5:W7)) | I6: =IF(COUNT(원본_CLI_ON!X5:X7)=0,"",AVERAGE(원본_CLI_ON!X5:X7)) | ... N6: =IF(COUNT(원본_CLI_ON!AC5:AC7)=0,"",AVERAGE(원본_CLI_ON!AC5:AC7))
A7: pose | B7: =IF(COUNT(원본_CLI_ON!Q8:Q10)=0,"",AVERAGE(원본_CLI_ON!Q8:Q10)) -> 25.497933 | C7: =IF(COUNT(원본_CLI_ON!R8:R10)=0,"",AVERAGE(원본_CLI_ON!R8:R10)) -> 17.208333 | D7: =IF(COUNT(원본_CLI_ON!S8:S10)=0,"",AVERAGE(원본_CLI_ON!S8:S10)) -> 674 | E7: =IF(COUNT(원본_CLI_ON!T8:T10)=0,"",AVERAGE(원본_CLI_ON!T8:T10)) -> 167.33333 | F7: =IF(COUNT(원본_CLI_ON!U8:U10)=0,"",AVERAGE(원본_CLI_ON!U8:U10)) | G7: =IF(COUNT(원본_CLI_ON!V8:V10)=0,"",AVERAGE(원본_CLI_ON!V8:V10)) | H7: =IF(COUNT(원본_CLI_ON!W8:W10)=0,"",AVERAGE(원본_CLI_ON!W8:W10)) -> 60.1761 | I7: =IF(COUNT(원본_CLI_ON!X8:X10)=0,"",AVERAGE(원본_CLI_ON!X8:X10)) | ... N7: =IF(COUNT(원본_CLI_ON!AC8:AC10)=0,"",AVERAGE(원본_CLI_ON!AC8:AC10)) -> 25.493467
A8: det_seg | B8: =IF(COUNT(원본_CLI_ON!Q11:Q13)=0,"",AVERAGE(원본_CLI_ON!Q11:Q13)) -> 43.5873 | C8: =IF(COUNT(원본_CLI_ON!R11:R13)=0,"",AVERAGE(원본_CLI_ON!R11:R13)) -> 23.015233 | D8: =IF(COUNT(원본_CLI_ON!S11:S13)=0,"",AVERAGE(원본_CLI_ON!S11:S13)) -> 1373.3333 | E8: =IF(COUNT(원본_CLI_ON!T11:T13)=0,"",AVERAGE(원본_CLI_ON!T11:T13)) -> 2824 | F8: =IF(COUNT(원본_CLI_ON!U11:U13)=0,"",AVERAGE(원본_CLI_ON!U11:U13)) -> 88.005533 | G8: =IF(COUNT(원본_CLI_ON!V11:V13)=0,"",AVERAGE(원본_CLI_ON!V11:V13)) -> 74.450067 | H8: =IF(COUNT(원본_CLI_ON!W11:W13)=0,"",AVERAGE(원본_CLI_ON!W11:W13)) | I8: =IF(COUNT(원본_CLI_ON!X11:X13)=0,"",AVERAGE(원본_CLI_ON!X11:X13)) -> 6.0502833 | ... N8: =IF(COUNT(원본_CLI_ON!AC11:AC13)=0,"",AVERAGE(원본_CLI_ON!AC11:AC13))
A9: det_pose | B9: =IF(COUNT(원본_CLI_ON!Q14:Q16)=0,"",AVERAGE(원본_CLI_ON!Q14:Q16)) -> 48.851867 | C9: =IF(COUNT(원본_CLI_ON!R14:R16)=0,"",AVERAGE(원본_CLI_ON!R14:R16)) -> 19.572067 | D9: =IF(COUNT(원본_CLI_ON!S14:S16)=0,"",AVERAGE(원본_CLI_ON!S14:S16)) -> 1368.3333 | E9: =IF(COUNT(원본_CLI_ON!T14:T16)=0,"",AVERAGE(원본_CLI_ON!T14:T16)) -> 1890 | F9: =IF(COUNT(원본_CLI_ON!U14:U16)=0,"",AVERAGE(원본_CLI_ON!U14:U16)) -> 76.932133 | G9: =IF(COUNT(원본_CLI_ON!V14:V16)=0,"",AVERAGE(원본_CLI_ON!V14:V16)) | H9: =IF(COUNT(원본_CLI_ON!W14:W16)=0,"",AVERAGE(원본_CLI_ON!W14:W16)) -> 71.451133 | I9: =IF(COUNT(원본_CLI_ON!X14:X16)=0,"",AVERAGE(원본_CLI_ON!X14:X16)) -> 5.3194733 | ... N9: =IF(COUNT(원본_CLI_ON!AC14:AC16)=0,"",AVERAGE(원본_CLI_ON!AC14:AC16)) -> 29.004
A10: seg_pose | B10: =IF(COUNT(원본_CLI_ON!Q17:Q19)=0,"",AVERAGE(원본_CLI_ON!Q17:Q19)) -> 43.6606 | C10: =IF(COUNT(원본_CLI_ON!R17:R19)=0,"",AVERAGE(원본_CLI_ON!R17:R19)) -> 23.8245 | D10: =IF(COUNT(원본_CLI_ON!S17:S19)=0,"",AVERAGE(원본_CLI_ON!S17:S19)) -> 1376.6667 | E10: =IF(COUNT(원본_CLI_ON!T17:T19)=0,"",AVERAGE(원본_CLI_ON!T17:T19)) -> 4249.6667 | F10: =IF(COUNT(원본_CLI_ON!U17:U19)=0,"",AVERAGE(원본_CLI_ON!U17:U19)) | G10: =IF(COUNT(원본_CLI_ON!V17:V19)=0,"",AVERAGE(원본_CLI_ON!V17:V19)) -> 86.913 | H10: =IF(COUNT(원본_CLI_ON!W17:W19)=0,"",AVERAGE(원본_CLI_ON!W17:W19)) -> 70.797467 | I10: =IF(COUNT(원본_CLI_ON!X17:X19)=0,"",AVERAGE(원본_CLI_ON!X17:X19)) | ... N10: =IF(COUNT(원본_CLI_ON!AC17:AC19)=0,"",AVERAGE(원본_CLI_ON!AC17:AC19)) -> 33.823633
A11: det_seg_pose | B11: =IF(COUNT(원본_CLI_ON!Q20:Q22)=0,"",AVERAGE(원본_CLI_ON!Q20:Q22)) -> 72.58 | C11: =IF(COUNT(원본_CLI_ON!R20:R22)=0,"",AVERAGE(원본_CLI_ON!R20:R22)) -> 21.706233 | D11: =IF(COUNT(원본_CLI_ON!S20:S22)=0,"",AVERAGE(원본_CLI_ON!S20:S22)) -> 2687 | E11: =IF(COUNT(원본_CLI_ON!T20:T22)=0,"",AVERAGE(원본_CLI_ON!T20:T22)) -> 5993.6667 | F11: =IF(COUNT(원본_CLI_ON!U20:U22)=0,"",AVERAGE(원본_CLI_ON!U20:U22)) -> 69.0013 | G11: =IF(COUNT(원본_CLI_ON!V20:V22)=0,"",AVERAGE(원본_CLI_ON!V20:V22)) -> 63.0992 | H11: =IF(COUNT(원본_CLI_ON!W20:W22)=0,"",AVERAGE(원본_CLI_ON!W20:W22)) -> 63.740633 | I11: =IF(COUNT(원본_CLI_ON!X20:X22)=0,"",AVERAGE(원본_CLI_ON!X20:X22)) -> 5.7678633 | ... N11: =IF(COUNT(원본_CLI_ON!AC20:AC22)=0,"",AVERAGE(원본_CLI_ON!AC20:AC22)) -> 32.104733

Sheet 재현성_노이즈
A1: 측정 노이즈 크기 — 같은 CLI OFF 조건의 세트 A vs 세트 C
A2: 둘 다 CLI를 안 쓴 동일 조건 실험이다. 여기서 나오는 차이율이 곧 이 실험 셋업의 "바닥 노이즈"이며, CLI 효과는 이보다 커야 의미가 있다.
A4: 조건 | B4: 지표 | C4: 모델 | D4: 세트 C 평균 | E4: 세트 A 평균 | F4: 차이율 (%) | G4: 참고: CLI 차이율 (%)
A5: det | B5: 지연시간(ms) | C5: det | D5: =AVERAGE(원본_CLI_OFF!G2:G4) -> 17.8358 | E5: =AVERAGE(참고_CLI_OFF_세트A!G2:G4) -> 17.940767 | F5: =IF(D5=0,"",(E5-D5)/D5) -> 0.0058851673 | G5: =조건별_비교!K5 -> 0.074797131
A6: seg | B6: 지연시간(ms) | C6: seg | D6: =AVERAGE(원본_CLI_OFF!J5:J7) -> 22.8428 | E6: =AVERAGE(참고_CLI_OFF_세트A!J5:J7) -> 23.0129 | F6: =IF(D6=0,"",(E6-D6)/D6) -> 0.0074465477 | G6: =조건별_비교!K9 -> 0.081210126
A7: pose | B7: 지연시간(ms) | C7: pose | D7: =AVERAGE(원본_CLI_OFF!M8:M10) -> 17.817933 | E7: =AVERAGE(참고_CLI_OFF_세트A!M8:M10) -> 18.016133 | F7: =IF(D7=0,"",(E7-D7)/D7) -> 0.011123625 | G7: =조건별_비교!K13 -> 0.10395332
A8: det_seg | B8: 지연시간(ms) | C8: det | D8: =AVERAGE(원본_CLI_OFF!G11:G13) -> 25.1568 | E8: =AVERAGE(참고_CLI_OFF_세트A!G11:G13) -> 25.308667 | F8: =IF(D8=0,"",(E8-D8)/D8) -> 0.0060368038 | G8: =조건별_비교!K17 -> 0.068369851
A9: det_seg | B9: 지연시간(ms) | C9: seg | D9: =AVERAGE(원본_CLI_OFF!J11:J13) -> 25.160733 | E9: =AVERAGE(참고_CLI_OFF_세트A!J11:J13) -> 25.346667 | F9: =IF(D9=0,"",(E9-D9)/D9) -> 0.0073898217 | G9: =조건별_비교!K18 -> 0.11406133
A10: det_pose | B10: 지연시간(ms) | C10: det | D10: =AVERAGE(원본_CLI_OFF!G14:G16) -> 20.723933 | E10: =AVERAGE(참고_CLI_OFF_세트A!G14:G16) -> 20.755433 | F10: =IF(D10=0,"",(E10-D10)/D10) -> 0.0015199817 | G10: =조건별_비교!K23 -> 0.13708305
A11: det_pose | B11: 지연시간(ms) | C11: pose | D11: =AVERAGE(원본_CLI_OFF!M14:M16) -> 20.745 | E11: =AVERAGE(참고_CLI_OFF_세트A!M14:M16) -> 20.755167 | F11: =IF(D11=0,"",(E11-D11)/D11) -> 0.00049007793 | G11: =조건별_비교!K24 -> 0.14167751
A12: seg_pose | B12: 지연시간(ms) | C12: seg | D12: =AVERAGE(원본_CLI_OFF!J17:J19) -> 25.523667 | E12: =AVERAGE(참고_CLI_OFF_세트A!J17:J19) -> 25.467233 | F12: =IF(D12=0,"",(E12-D12)/D12) -> -0.0022110198 | G12: =조건별_비교!K29 -> 0.14567003
A13: seg_pose | B13: 지연시간(ms) | C13: pose | D13: =AVERAGE(원본_CLI_OFF!M17:M19) -> 25.564967 | E13: =AVERAGE(참고_CLI_OFF_세트A!M17:M19) -> 25.577 | F13: =IF(D13=0,"",(E13-D13)/D13) -> 0.00047069623 | G13: =조건별_비교!K30 -> 0.087901542
A14: det_seg_pose | B14: 지연시간(ms) | C14: det | D14: =AVERAGE(원본_CLI_OFF!G20:G22) -> 25.936333 | E14: =AVERAGE(참고_CLI_OFF_세트A!G20:G22) -> 26.125433 | F14: =IF(D14=0,"",(E14-D14)/D14) -> 0.0072909304 | G14: =조건별_비교!K35 -> 0.011245486
A15: det_seg_pose | B15: 지연시간(ms) | C15: seg | D15: =AVERAGE(원본_CLI_OFF!J20:J22) -> 25.818167 | E15: =AVERAGE(참고_CLI_OFF_세트A!J20:J22) -> 26.023 | F15: =IF(D15=0,"",(E15-D15)/D15) -> 0.0079336901 | G15: =조건별_비교!K36 -> 0.033734644
A16: det_seg_pose | B16: 지연시간(ms) | C16: pose | D16: =AVERAGE(원본_CLI_OFF!M20:M22) -> 25.860033 | E16: =AVERAGE(참고_CLI_OFF_세트A!M20:M22) -> 26.0866 | F16: =IF(D16=0,"",(E16-D16)/D16) -> 0.0087612674 | G16: =조건별_비교!K37 -> 0.032179644
A17: det | B17: FPS | C17: det | D17: =AVERAGE(원본_CLI_OFF!H2:H4) -> 42.3454 | E17: =AVERAGE(참고_CLI_OFF_세트A!H2:H4) -> 42.092733 | F17: =IF(D17=0,"",(E17-D17)/D17) -> -0.0059668032 | G17: =조건별_비교!K6 -> -0.057371836
A18: seg | B18: FPS | C18: seg | D18: =AVERAGE(원본_CLI_OFF!K5:K7) -> 34.6877 | E18: =AVERAGE(참고_CLI_OFF_세트A!K5:K7) -> 34.609567 | F18: =IF(D18=0,"",(E18-D18)/D18) -> -0.0022524795 | G18: =조건별_비교!K10 -> -0.058569272
A19: pose | B19: FPS | C19: pose | D19: =AVERAGE(원본_CLI_OFF!N8:N10) -> 42.374167 | E19: =AVERAGE(참고_CLI_OFF_세트A!N8:N10) -> 41.930333 | F19: =IF(D19=0,"",(E19-D19)/D19) -> -0.010474149 | G19: =조건별_비교!K14 -> -0.076991878
A20: det_seg | B20: FPS | C20: det | D20: =AVERAGE(원본_CLI_OFF!H11:H13) -> 32.0327 | E20: =AVERAGE(참고_CLI_OFF_세트A!H11:H13) -> 31.895967 | F20: =IF(D20=0,"",(E20-D20)/D20) -> -0.0042685547 | G20: =조건별_비교!K19 -> -0.054572359
A21: det_seg | B21: FPS | C21: seg | D21: =AVERAGE(원본_CLI_OFF!K11:K13) -> 31.985867 | E21: =AVERAGE(참고_CLI_OFF_세트A!K11:K13) -> 31.803867 | F21: =IF(D21=0,"",(E21-D21)/D21) -> -0.0056900131 | G21: =조건별_비교!K20 -> -0.085769131
A22: det_pose | B22: FPS | C22: det | D22: =AVERAGE(원본_CLI_OFF!H14:H16) -> 38.236 | E22: =AVERAGE(참고_CLI_OFF_세트A!H14:H16) -> 38.280533 | F22: =IF(D22=0,"",(E22-D22)/D22) -> 0.0011646964 | G22: =조건별_비교!K25 -> -0.097095233
A23: det_pose | B23: FPS | C23: pose | D23: =AVERAGE(원본_CLI_OFF!N14:N16) -> 38.2378 | E23: =AVERAGE(참고_CLI_OFF_세트A!N14:N16) -> 38.300967 | F23: =IF(D23=0,"",(E23-D23)/D23) -> 0.001651943 | G23: =조건별_비교!K26 -> -0.10062294
A24: seg_pose | B24: FPS | C24: seg | D24: =AVERAGE(원본_CLI_OFF!K17:K19) -> 31.583133 | E24: =AVERAGE(참고_CLI_OFF_세트A!K17:K19) -> 31.578433 | F24: =IF(D24=0,"",(E24-D24)/D24) -> -0.00014881361 | G24: =조건별_비교!K31 -> -0.1055479
A25: seg_pose | B25: FPS | C25: pose | D25: =AVERAGE(원본_CLI_OFF!N17:N19) -> 31.645 | E25: =AVERAGE(참고_CLI_OFF_세트A!N17:N19) -> 31.585033 | F25: =IF(D25=0,"",(E25-D25)/D25) -> -0.0018949808 | G25: =조건별_비교!K32 -> -0.068283562
A26: det_seg_pose | B26: FPS | C26: det | D26: =AVERAGE(원본_CLI_OFF!H20:H22) -> 31.712367 | E26: =AVERAGE(참고_CLI_OFF_세트A!H20:H22) -> 31.730767 | F26: =IF(D26=0,"",(E26-D26)/D26) -> 0.00058021529 | G26: =조건별_비교!K38 -> -0.017080613
A27: det_seg_pose | B27: FPS | C27: seg | D27: =AVERAGE(원본_CLI_OFF!K20:K22) -> 31.702267 | E27: =AVERAGE(참고_CLI_OFF_세트A!K20:K22) -> 31.725933 | F27: =IF(D27=0,"",(E27-D27)/D27) -> 0.00074652917 | G27: =조건별_비교!K39 -> -0.021926928
A28: det_seg_pose | B28: FPS | C28: pose | D28: =AVERAGE(원본_CLI_OFF!N20:N22) -> 31.739767 | E28: =AVERAGE(참고_CLI_OFF_세트A!N20:N22) -> 31.7307 | F28: =IF(D28=0,"",(E28-D28)/D28) -> -0.00028565637 | G28: =조건별_비교!K40 -> -0.021138572
A29: det | B29: CPU(%) | C29: - | D29: =AVERAGE(원본_CLI_OFF!O2:O4) -> 12.7268 | E29: =AVERAGE(참고_CLI_OFF_세트A!O2:O4) -> 12.400967 | F29: =IF(D29=0,"",(E29-D29)/D29) -> -0.025602141 | G29: =조건별_비교!K7 -> -0.0096463107
A30: seg | B30: CPU(%) | C30: - | D30: =AVERAGE(원본_CLI_OFF!O5:O7) -> 10.9258 | E30: =AVERAGE(참고_CLI_OFF_세트A!O5:O7) -> 10.983267 | F30: =IF(D30=0,"",(E30-D30)/D30) -> 0.0052597216 | G30: =조건별_비교!K11 -> -0.039817069
A31: pose | B31: CPU(%) | C31: - | D31: =AVERAGE(원본_CLI_OFF!O8:O10) -> 12.725867 | E31: =AVERAGE(참고_CLI_OFF_세트A!O8:O10) -> 12.699167 | F31: =IF(D31=0,"",(E31-D31)/D31) -> -0.0020980889 | G31: =조건별_비교!K15 -> -0.03132727
A32: det_seg | B32: CPU(%) | C32: - | D32: =AVERAGE(원본_CLI_OFF!O11:O13) -> 19.154233 | E32: =AVERAGE(참고_CLI_OFF_세트A!O11:O13) -> 19.0269 | F32: =IF(D32=0,"",(E32-D32)/D32) -> -0.0066477907 | G32: =조건별_비교!K21 -> -0.058129883
A33: det_pose | B33: CPU(%) | C33: - | D33: =AVERAGE(원본_CLI_OFF!O14:O16) -> 21.226433 | E33: =AVERAGE(참고_CLI_OFF_세트A!O14:O16) -> 21.072533 | F33: =IF(D33=0,"",(E33-D33)/D33) -> -0.0072503938 | G33: =조건별_비교!K27 -> -0.070266162
A34: seg_pose | B34: CPU(%) | C34: - | D34: =AVERAGE(원본_CLI_OFF!O17:O19) -> 19.048767 | E34: =AVERAGE(참고_CLI_OFF_세트A!O17:O19) -> 19.074833 | F34: =IF(D34=0,"",(E34-D34)/D34) -> 0.0013684176 | G34: =조건별_비교!K33 -> -0.069729799
A35: det_seg_pose | B35: CPU(%) | C35: - | D35: =AVERAGE(원본_CLI_OFF!O20:O22) -> 26.948033 | E35: =AVERAGE(참고_CLI_OFF_세트A!O20:O22) -> 26.431467 | F35: =IF(D35=0,"",(E35-D35)/D35) -> -0.019168993 | G35: =조건별_비교!K41 -> -0.056507525
A36: det | B36: MEM(%) | C36: - | D36: =AVERAGE(원본_CLI_OFF!P2:P4) -> 6.80632 | E36: =AVERAGE(참고_CLI_OFF_세트A!P2:P4) -> 8.45525 | F36: =IF(D36=0,"",(E36-D36)/D36) -> 0.24226454 | G36: =조건별_비교!K8 -> 0.1665599
A37: seg | B37: MEM(%) | C37: - | D37: =AVERAGE(원본_CLI_OFF!P5:P7) -> 6.9555533 | E37: =AVERAGE(참고_CLI_OFF_세트A!P5:P7) -> 8.5327933 | F37: =IF(D37=0,"",(E37-D37)/D37) -> 0.22675982 | G37: =조건별_비교!K12 -> 0.16486012
A38: pose | B38: MEM(%) | C38: - | D38: =AVERAGE(원본_CLI_OFF!P8:P10) -> 6.97832 | E38: =AVERAGE(참고_CLI_OFF_세트A!P8:P10) -> 8.4875133 | F38: =IF(D38=0,"",(E38-D38)/D38) -> 0.21626886 | G38: =조건별_비교!K16 -> 0.13806809
A39: det_seg | B39: MEM(%) | C39: - | D39: =AVERAGE(원본_CLI_OFF!P11:P13) -> 7.863 | E39: =AVERAGE(참고_CLI_OFF_세트A!P11:P13) -> 9.3946233 | F39: =IF(D39=0,"",(E39-D39)/D39) -> 0.19478867 | G39: =조건별_비교!K22 -> 0.079713002
A40: det_pose | B40: MEM(%) | C40: - | D40: =AVERAGE(원본_CLI_OFF!P14:P16) -> 7.81261 | E40: =AVERAGE(참고_CLI_OFF_세트A!P14:P16) -> 9.6238633 | F40: =IF(D40=0,"",(E40-D40)/D40) -> 0.23183716 | G40: =조건별_비교!K28 -> 0.09469648
A41: seg_pose | B41: MEM(%) | C41: - | D41: =AVERAGE(원본_CLI_OFF!P17:P19) -> 8.1872 | E41: =AVERAGE(참고_CLI_OFF_세트A!P17:P19) -> 9.3719733 | F41: =IF(D41=0,"",(E41-D41)/D41) -> 0.14471044 | G41: =조건별_비교!K34 -> 0.060489952
...
