Workbook

Sheet 설명
A1: NPU vs CPU 후처리 비교 (v5det 실험) — 컬럼/시트 설명
A3: 실험 | B3: Detection 모델(YOLOv5) 후처리(NMS)를 NPU(neural core, engine=nn_core/auto, yolov5xs_wo_spp_nms_core.hef)에서 vs CPU(host, engine=cpu, yolov5xs_wo_spp.hef)에서 돌렸을 때 차이 비교. Segmentation/Pose는 두 조건 다 YOLOv8 CPU 후처리 그대로(이 아키텍처엔 NPU 후처리 옵션 자체가 없음).
A4: 조합 | B4: det / det_seg / det_pose / det_seg_pose 4가지 (Detection은 실험 축이라 항상 켜둠), 각 3회 반복이 목표지만 세그폴트 재시도 로직 때문에 det 조합은 CSV 행이 18개까지 쌓임(전부 유효한 반복 측정값 — 그중 hrtt 트레이스가 붙은 건 3개뿐).
A5: postprocess_engine / combo | B5: '전체' 시트에 원본 CSV엔 없던 두 컬럼을 앞에 추가해 구분용으로 씀.
A7: [중요] HRTT 트레이스 길이 관련 주의사항
A8: HAILO_TRACE_TIME_IN_SECONDS_BOUNDED_DUMP 환경변수 값을 처음엔 90 -> 30 -> 3으로 낮춰가며 재수집했다. 실기로 직접 확인한 결과 이 값은 '그 시점까지 전체 누적'이 아니라 '최근 N초 구간만 덤프'하는 방식으로 보인다(det 단독 트레이스의 hrtt_run_time_sec가 실제 실행시간 9.6초가 아니라 설정값과 비슷한 2.8~2.9초로 나옴). 그 결과: - det_seg_pose 조합(3개 값 다 최초 30/90 설정으로 수집됨, 실제 실행시간 ~90~100초에 근접한 구간을 담고 있어 상대적으로 대표성이 높음) - det / det_seg / det_pose 조합(이번에 3초 설정으로 새로 수집, 전체 실행시간 중 최근 ~2.8초 구간만 반영 — 표본이 훨씬 작음) 따라서 avg_fps_det / avg_latency_det / max_latency_det / activation_det 등 'hrtt 기반' 컬럼은 조합마다 대표하는 시간 구간 길이가 다르다는 점을 감안해서 봐야 한다. 반대로 det_latency_ms / seg_latency_ms / pose_latency_ms / cpu_percent / postprocess_ms_* / total_time_ms_* 컬럼은 앱이 673장 전체를 처리하면서 직접 측정한 값이라 이 트레이스 길이 이슈와 무관하게 항상 전체 실행 기준이다 — 조합 간 1차 비교는 이 쪽을 기준으로 하는 게 안전하다.
A10: det/seg/pose_latency_ms | B10: 모델별 평균 추론 latency(HailoRT vstream write→read 왕복시간, ms). 큐 대기시간까지 포함 — 항상 673장 전체 기준(트레이스 길이 이슈 없음).
A11: cpu_percent / mem_percent | B11: 실행 구간 전체 호스트 CPU/메모리 사용률(%).
A12: npu_percent | B12: hrtt 트레이스의 모델별 device_usage_pct 합으로 채움(외부 폴링 스크립트가 이 실기 환경에서 샘플을 못 얻어서 대체). '어떤 모델이든 NPU를 쓰고 있던 비율' 추정치.
A13: avg_fps_*/avg_latency_*/max_latency_*/activation_* | B13: hrtt 트레이스 기반 — 위 caveat 참고, 조합별로 반영하는 시간 구간 길이가 다름.
A14: switches_per_s / idle_time_pct | B14: hrtt 트레이스 전체 기준 글로벌 지표(스케줄러 코어옵 전환 빈도, 유휴비율).
A15: postprocess_ms_* / total_time_ms_* / avg_preprocess_ms_* | B15: 장당 평균, 앱이 직접 측정(673장 전체 기준).
A16: n_total_rows / n_hrtt_rows | B16: '케이스별_평균' 시트에서 추가한 컬럼 — 그 (엔진,조합)에 CSV 행이 몇 개 있는지 / 그중 hrtt 트레이스가 매칭된 게 몇 개인지.

Sheet 전체
A1: postprocess_engine | B1: combo | C1: run_id | D1: use_det | E1: use_seg | F1: use_pose | G1: batch_det | H1: batch_seg | I1: batch_pose | J1: threshold_det | K1: threshold_seg | L1: threshold_pose | M1: timeout_ms | N1: priority_det | O1: priority_seg | P1: priority_pose | Q1: det_latency_ms | R1: seg_latency_ms | S1: pose_latency_ms | T1: cpu_percent | U1: mem_percent | V1: voluntary_ctx_switches | W1: nonvoluntary_ctx_switches | X1: npu_percent | Y1: switches_per_s | Z1: idle_time_pct | AA1: run_time_s | AB1: avg_fps_det | AC1: avg_latency_det | AD1: max_latency_det | AE1: activation_det | AF1: avg_fps_seg | AG1: avg_latency_seg | AH1: max_latency_seg | AI1: activation_seg | AJ1: avg_fps_pose | AK1: avg_latency_pose | AL1: max_latency_pose | AM1: activation_pose | AN1: total_time_det_s | AO1: total_time_seg_s | AP1: total_time_pose_s | AQ1: avg_preprocess_ms_det | AR1: avg_preprocess_ms_seg | AS1: avg_preprocess_ms_pose | AT1: postprocess_ms_det | AU1: postprocess_ms_seg | AV1: postprocess_ms_pose | AW1: total_time_ms_det | AX1: total_time_ms_seg | AY1: total_time_ms_pose
A2: NPU | B2: det | C2: 1 | D2: 1 | E2: 0 | F2: 0 | G2: 1 | H2: 1 | I2: 1 | J2: 1 | K2: 1 | L2: 1 | M2: 0 | N2: 0 | O2: 0 | P2: 0 | Q2: 152.881 | R2: NaN | S2: NaN | T2: 23.3098 | U2: 20.4009 | V2: 1336 | W2: 748 | X2: NaN | Y2: NaN | Z2: NaN | AA2: 9.62532 | AB2: NaN | AC2: NaN | AD2: NaN | AE2: NaN | AF2: NaN | AG2: NaN | AH2: NaN | AI2: NaN | AJ2: NaN | AK2: NaN | AL2: NaN | AM2: NaN | AN2: 9.6129 | AO2: NaN | AP2: NaN | AQ2: 4.91882 | AR2: NaN | AS2: NaN | AT2: 0.0110146 | AU2: NaN | AV2: NaN | AW2: 157.81 | AX2: NaN | AY2: NaN
A3: NPU | B3: det | C3: 2 | D3: 1 | E3: 0 | F3: 0 | G3: 1 | H3: 1 | I3: 1 | J3: 1 | K3: 1 | L3: 1 | M3: 0 | N3: 0 | O3: 0 | P3: 0 | Q3: 152.921 | R3: NaN | S3: NaN | T3: 22.6509 | U3: 20.1188 | V3: 1337 | W3: 760 | X3: NaN | Y3: NaN | Z3: NaN | AA3: 9.62351 | AB3: NaN | AC3: NaN | AD3: NaN | AE3: NaN | AF3: NaN | AG3: NaN | AH3: NaN | AI3: NaN | AJ3: NaN | AK3: NaN | AL3: NaN | AM3: NaN | AN3: 9.61139 | AO3: NaN | AP3: NaN | AQ3: 4.81591 | AR3: NaN | AS3: NaN | AT3: 0.00992016 | AU3: NaN | AV3: NaN | AW3: 157.747 | AX3: NaN | AY3: NaN
A4: NPU | B4: det | C4: 3 | D4: 1 | E4: 0 | F4: 0 | G4: 1 | H4: 1 | I4: 1 | J4: 1 | K4: 1 | L4: 1 | M4: 0 | N4: 0 | O4: 0 | P4: 0 | Q4: 152.94 | R4: NaN | S4: NaN | T4: 22.8834 | U4: 19.8167 | V4: 1336 | W4: 661 | X4: NaN | Y4: NaN | Z4: NaN | AA4: 9.6242 | AB4: NaN | AC4: NaN | AD4: NaN | AE4: NaN | AF4: NaN | AG4: NaN | AH4: NaN | AI4: NaN | AJ4: NaN | AK4: NaN | AL4: NaN | AM4: NaN | AN4: 9.6121 | AO4: NaN | AP4: NaN | AQ4: 4.88137 | AR4: NaN | AS4: NaN | AT4: 0.0102496 | AU4: NaN | AV4: NaN | AW4: 157.832 | AX4: NaN | AY4: NaN
A5: NPU | B5: det | C5: 13 | D5: 1 | E5: 0 | F5: 0 | G5: 1 | H5: 1 | I5: 1 | J5: 1 | K5: 1 | L5: 1 | M5: 0 | N5: 0 | O5: 0 | P5: 0 | Q5: 152.733 | R5: NaN | S5: NaN | T5: 23.0952 | U5: 27.5931 | V5: 1336 | W5: 1027 | X5: NaN | Y5: NaN | Z5: NaN | AA5: 9.62273 | AB5: NaN | AC5: NaN | AD5: NaN | AE5: NaN | AF5: NaN | AG5: NaN | AH5: NaN | AI5: NaN | AJ5: NaN | AK5: NaN | AL5: NaN | AM5: NaN | AN5: 9.61041 | AO5: NaN | AP5: NaN | AQ5: 5.05993 | AR5: NaN | AS5: NaN | AT5: 0.010345 | AU5: NaN | AV5: NaN | AW5: 157.803 | AX5: NaN | AY5: NaN
A6: NPU | B6: det | C6: 14 | D6: 1 | E6: 0 | F6: 0 | G6: 1 | H6: 1 | I6: 1 | J6: 1 | K6: 1 | L6: 1 | M6: 0 | N6: 0 | O6: 0 | P6: 0 | Q6: 152.514 | R6: NaN | S6: NaN | T6: 24.1027 | U6: 26.8478 | V6: 1336 | W6: 713 | X6: NaN | Y6: NaN | Z6: NaN | AA6: 9.62203 | AB6: NaN | AC6: NaN | AD6: NaN | AE6: NaN | AF6: NaN | AG6: NaN | AH6: NaN | AI6: NaN | AJ6: NaN | AK6: NaN | AL6: NaN | AM6: NaN | AN6: 9.60961 | AO6: NaN | AP6: NaN | AQ6: 5.23634 | AR6: NaN | AS6: NaN | AT6: 0.0100743 | AU6: NaN | AV6: NaN | AW6: 157.76 | AX6: NaN | AY6: NaN
A7: NPU | B7: det | C7: 15 | D7: 1 | E7: 0 | F7: 0 | G7: 1 | H7: 1 | I7: 1 | J7: 1 | K7: 1 | L7: 1 | M7: 0 | N7: 0 | O7: 0 | P7: 0 | Q7: 152.781 | R7: NaN | S7: NaN | T7: 23.4956 | U7: 27.2831 | V7: 1336 | W7: 694 | X7: NaN | Y7: NaN | Z7: NaN | AA7: 9.62306 | AB7: NaN | AC7: NaN | AD7: NaN | AE7: NaN | AF7: NaN | AG7: NaN | AH7: NaN | AI7: NaN | AJ7: NaN | AK7: NaN | AL7: NaN | AM7: NaN | AN7: 9.6109 | AO7: NaN | AP7: NaN | AQ7: 5.02521 | AR7: NaN | AS7: NaN | AT7: 0.0102314 | AU7: NaN | AV7: NaN | AW7: 157.816 | AX7: NaN | AY7: NaN
A8: NPU | B8: det | C8: 16 | D8: 1 | E8: 0 | F8: 0 | G8: 1 | H8: 1 | I8: 1 | J8: 1 | K8: 1 | L8: 1 | M8: 0 | N8: 0 | O8: 0 | P8: 0 | Q8: 152.546 | R8: NaN | S8: NaN | T8: 23.6158 | U8: 26.6239 | V8: 1335 | W8: 652 | X8: NaN | Y8: NaN | Z8: NaN | AA8: 9.61848 | AB8: NaN | AC8: NaN | AD8: NaN | AE8: NaN | AF8: NaN | AG8: NaN | AH8: NaN | AI8: NaN | AJ8: NaN | AK8: NaN | AL8: NaN | AM8: NaN | AN8: 9.60631 | AO8: NaN | AP8: NaN | AQ8: 5.07139 | AR8: NaN | AS8: NaN | AT8: 0.0111137 | AU8: NaN | AV8: NaN | AW8: 157.628 | AX8: NaN | AY8: NaN
A9: NPU | B9: det | C9: 17 | D9: 1 | E9: 0 | F9: 0 | G9: 1 | H9: 1 | I9: 1 | J9: 1 | K9: 1 | L9: 1 | M9: 0 | N9: 0 | O9: 0 | P9: 0 | Q9: 152.944 | R9: NaN | S9: NaN | T9: 21.8965 | U9: 26.8381 | V9: 1337 | W9: 564 | X9: NaN | Y9: NaN | Z9: NaN | AA9: 9.6192 | AB9: NaN | AC9: NaN | AD9: NaN | AE9: NaN | AF9: NaN | AG9: NaN | AH9: NaN | AI9: NaN | AJ9: NaN | AK9: NaN | AL9: NaN | AM9: NaN | AN9: 9.60685 | AO9: NaN | AP9: NaN | AQ9: 4.73774 | AR9: NaN | AS9: NaN | AT9: 0.00975257 | AU9: NaN | AV9: NaN | AW9: 157.692 | AX9: NaN | AY9: NaN
A10: NPU | B10: det | C10: 18 | D10: 1 | E10: 0 | F10: 0 | G10: 1 | H10: 1 | I10: 1 | J10: 1 | K10: 1 | L10: 1 | M10: 0 | N10: 0 | O10: 0 | P10: 0 | Q10: 152.761 | R10: NaN | S10: NaN | T10: 22.3833 | U10: 26.4932 | V10: 1334 | W10: 593 | X10: NaN | Y10: NaN | Z10: NaN | AA10: 9.62177 | AB10: NaN | AC10: NaN | AD10: NaN | AE10: NaN | AF10: NaN | AG10: NaN | AH10: NaN | AI10: NaN | AJ10: NaN | AK10: NaN | AL10: NaN | AM10: NaN | AN10: 9.60936 | AO10: NaN | AP10: NaN | AQ10: 4.86762 | AR10: NaN | AS10: NaN | AT10: 0.0107095 | AU10: NaN | AV10: NaN | AW10: 157.639 | AX10: NaN | AY10: NaN
A11: NPU | B11: det | C11: 19 | D11: 1 | E11: 0 | F11: 0 | G11: 1 | H11: 1 | I11: 1 | J11: 1 | K11: 1 | L11: 1 | M11: 0 | N11: 0 | O11: 0 | P11: 0 | Q11: 152.759 | R11: NaN | S11: NaN | T11: 23.1031 | U11: 26.9634 | V11: 1337 | W11: 622 | X11: NaN | Y11: NaN | Z11: NaN | AA11: 9.62059 | AB11: NaN | AC11: NaN | AD11: NaN | AE11: NaN | AF11: NaN | AG11: NaN | AH11: NaN | AI11: NaN | AJ11: NaN | AK11: NaN | AL11: NaN | AM11: NaN | AN11: 9.60848 | AO11: NaN | AP11: NaN | AQ11: 4.96819 | AR11: NaN | AS11: NaN | AT11: 0.0100511 | AU11: NaN | AV11: NaN | AW11: 157.737 | AX11: NaN | AY11: NaN
A12: NPU | B12: det | C12: 20 | D12: 1 | E12: 0 | F12: 0 | G12: 1 | H12: 1 | I12: 1 | J12: 1 | K12: 1 | L12: 1 | M12: 0 | N12: 0 | O12: 0 | P12: 0 | Q12: 152.911 | R12: NaN | S12: NaN | T12: 22.6187 | U12: 26.9929 | V12: 1336 | W12: 931 | X12: NaN | Y12: NaN | Z12: NaN | AA12: 9.62139 | AB12: NaN | AC12: NaN | AD12: NaN | AE12: NaN | AF12: NaN | AG12: NaN | AH12: NaN | AI12: NaN | AJ12: NaN | AK12: NaN | AL12: NaN | AM12: NaN | AN12: 9.60917 | AO12: NaN | AP12: NaN | AQ12: 4.83961 | AR12: NaN | AS12: NaN | AT12: 0.010004 | AU12: NaN | AV12: NaN | AW12: 157.761 | AX12: NaN | AY12: NaN
A13: NPU | B13: det | C13: 21 | D13: 1 | E13: 0 | F13: 0 | G13: 1 | H13: 1 | I13: 1 | J13: 1 | K13: 1 | L13: 1 | M13: 0 | N13: 0 | O13: 0 | P13: 0 | Q13: 152.686 | R13: NaN | S13: NaN | T13: 23.5063 | U13: 26.7992 | V13: 1336 | W13: 633 | X13: NaN | Y13: NaN | Z13: NaN | AA13: 9.62097 | AB13: NaN | AC13: NaN | AD13: NaN | AE13: NaN | AF13: NaN | AG13: NaN | AH13: NaN | AI13: NaN | AJ13: NaN | AK13: NaN | AL13: NaN | AM13: NaN | AN13: 9.60874 | AO13: NaN | AP13: NaN | AQ13: 5.05571 | AR13: NaN | AS13: NaN | AT13: 0.0100083 | AU13: NaN | AV13: NaN | AW13: 157.752 | AX13: NaN | AY13: NaN
... A16: NPU | B16: det | C16: 24 | D16: 1 | E16: 0 | F16: 0 | G16: 1 | H16: 1 | I16: 1 | J16: 1 | K16: 1 | L16: 1 | M16: 0 | N16: 0 | O16: 0 | P16: 0 | Q16: 152.601 | R16: NaN | S16: NaN | T16: 23.8782 | U16: 26.5772 | V16: 1337 | W16: 828 | X16: NaN | Y16: NaN | Z16: NaN | AA16: 9.62048 | AB16: NaN | AC16: NaN | AD16: NaN | AE16: NaN | AF16: NaN | AG16: NaN | AH16: NaN | AI16: NaN | AJ16: NaN | AK16: NaN | AL16: NaN | AM16: NaN | AN16: 9.60836 | AO16: NaN | AP16: NaN | AQ16: 5.11689 | AR16: NaN | AS16: NaN | AT16: 0.0108209 | AU16: NaN | AV16: NaN | AW16: 157.729 | AX16: NaN | AY16: NaN
A17: NPU | B17: det | C17: 31 | D17: 1 | E17: 0 | F17: 0 | G17: 1 | H17: 1 | I17: 1 | J17: 1 | K17: 1 | L17: 1 | M17: 0 | N17: 0 | O17: 0 | P17: 0 | Q17: 152.637 | R17: NaN | S17: NaN | T17: 23.1637 | U17: 27.3479 | V17: 1339 | W17: 687 | X17: 99.141 | Y17: 0.358 | Z17: 0.859 | AA17: 9.6293 | AB17: 69.378 | AC17: 110.12 | AD17: 117.061 | AE17: 24.001 | AF17: NaN | AG17: NaN | AH17: NaN | AI17: NaN | AJ17: NaN | AK17: NaN | AL17: NaN | AM17: NaN | AN17: 9.61691 | AO17: NaN | AP17: NaN | AQ17: 5.2037 | AR17: NaN | AS17: NaN | AT17: 0.00977905 | AU17: NaN | AV17: NaN | AW17: 157.85 | AX17: NaN | AY17: NaN
A18: NPU | B18: det | C18: 32 | D18: 1 | E18: 0 | F18: 0 | G18: 1 | H18: 1 | I18: 1 | J18: 1 | K18: 1 | L18: 1 | M18: 0 | N18: 0 | O18: 0 | P18: 0 | Q18: 152.881 | R18: NaN | S18: NaN | T18: 22.5688 | U18: 26.6483 | V18: 1337 | W18: 765 | X18: 99.406 | Y18: 0.359 | Z18: 0.594 | AA18: 9.62555 | AB18: 69.557 | AC18: 111.525 | AD18: 114.546 | AE18: 16.558 | AF18: NaN | AG18: NaN | AH18: NaN | AI18: NaN | AJ18: NaN | AK18: NaN | AL18: NaN | AM18: NaN | AN18: 9.61346 | AO18: NaN | AP18: NaN | AQ18: 4.92048 | AR18: NaN | AS18: NaN | AT18: 0.00955413 | AU18: NaN | AV18: NaN | AW18: 157.811 | AX18: NaN | AY18: NaN
A19: NPU | B19: det | C19: 33 | D19: 1 | E19: 0 | F19: 0 | G19: 1 | H19: 1 | I19: 1 | J19: 1 | K19: 1 | L19: 1 | M19: 0 | N19: 0 | O19: 0 | P19: 0 | Q19: 152.649 | R19: NaN | S19: NaN | T19: 22.9134 | U19: 26.7507 | V19: 1336 | W19: 662 | X19: 99.463 | Y19: 0.359 | Z19: 0.537 | AA19: 9.61992 | AB19: 69.62 | AC19: 111.561 | AD19: 117.791 | AE19: 14.948 | AF19: NaN | AG19: NaN | AH19: NaN | AI19: NaN | AJ19: NaN | AK19: NaN | AL19: NaN | AM19: NaN | AN19: 9.60751 | AO19: NaN | AP19: NaN | AQ19: 5.04777 | AR19: NaN | AS19: NaN | AT19: 0.0096626 | AU19: NaN | AV19: NaN | AW19: 157.706 | AX19: NaN | AY19: NaN
A20: NPU | B20: det_seg | C20: 4 | D20: 1 | E20: 1 | F20: 0 | G20: 1 | H20: 1 | I20: 1 | J20: 1 | K20: 1 | L20: 1 | M20: 0 | N20: 0 | O20: 0 | P20: 0 | Q20: 792.667 | R20: 826.05 | S20: NaN | T20: 40.6799 | U20: 20.3594 | V20: 8146 | W20: 5489 | X20: NaN | Y20: NaN | Z20: NaN | AA20: 59.2095 | AB20: NaN | AC20: NaN | AD20: NaN | AE20: NaN | AF20: NaN | AG20: NaN | AH20: NaN | AI20: NaN | AJ20: NaN | AK20: NaN | AL20: NaN | AM20: NaN | AN20: 59.0867 | AO20: 59.0373 | AP20: NaN | AQ20: 5.46775 | AR20: 5.15087 | AS20: NaN | AT20: 0.0106914 | AU20: 37.6213 | AV20: NaN | AW20: 798.145 | AX20: 868.822 | AY20: NaN
A21: NPU | B21: det_seg | C21: 5 | D21: 1 | E21: 1 | F21: 0 | G21: 1 | H21: 1 | I21: 1 | J21: 1 | K21: 1 | L21: 1 | M21: 0 | N21: 0 | O21: 0 | P21: 0 | Q21: 788.93 | R21: 822.028 | S21: NaN | T21: 41.0349 | U21: 20.4536 | V21: 8187 | W21: 5563 | X21: NaN | Y21: NaN | Z21: NaN | AA21: 58.941 | AB21: NaN | AC21: NaN | AD21: NaN | AE21: NaN | AF21: NaN | AG21: NaN | AH21: NaN | AI21: NaN | AJ21: NaN | AK21: NaN | AL21: NaN | AM21: NaN | AN21: 58.8227 | AO21: 58.7699 | AP21: NaN | AQ21: 5.57967 | AR21: 5.11583 | AS21: NaN | AT21: 0.0105358 | AU21: 37.6231 | AV21: NaN | AW21: 794.52 | AX21: 864.767 | AY21: NaN
A22: NPU | B22: det_seg | C22: 6 | D22: 1 | E22: 1 | F22: 0 | G22: 1 | H22: 1 | I22: 1 | J22: 1 | K22: 1 | L22: 1 | M22: 0 | N22: 0 | O22: 0 | P22: 0 | Q22: 795.642 | R22: 829.386 | S22: NaN | T22: 40.7169 | U22: 20.3569 | V22: 8204 | W22: 4954 | X22: NaN | Y22: NaN | Z22: NaN | AA22: 59.4241 | AB22: NaN | AC22: NaN | AD22: NaN | AE22: NaN | AF22: NaN | AG22: NaN | AH22: NaN | AI22: NaN | AJ22: NaN | AK22: NaN | AL22: NaN | AM22: NaN | AN22: 59.3012 | AO22: 59.2525 | AP22: NaN | AQ22: 5.51006 | AR22: 5.09479 | AS22: NaN | AT22: 0.0103725 | AU22: 37.5291 | AV22: NaN | AW22: 801.162 | AX22: 872.01 | AY22: NaN
A23: NPU | B23: det_seg | C23: 25 | D23: 1 | E23: 1 | F23: 0 | G23: 1 | H23: 1 | I23: 1 | J23: 1 | K23: 1 | L23: 1 | M23: 0 | N23: 0 | O23: 0 | P23: 0 | Q23: 607.042 | R23: 642.802 | S23: NaN | T23: 43.5843 | U23: 27.4849 | V23: 8266 | W23: 5529 | X23: 99.912 | Y23: 27.736 | Z23: 0.088 | AA23: 45.2919 | AB23: 13.851 | AC23: 23.687 | AD23: 33.086 | AE23: 16.486 | AF23: 13.851 | AG23: 25.158 | AH23: 169.833 | AI23: 1.938 | AJ23: NaN | AK23: NaN | AL23: NaN | AM23: NaN | AN23: 45.0645 | AO23: 45.1194 | AP23: NaN | AQ23: 5.71055 | AR23: 5.29501 | AS23: NaN | AT23: 0.0105543 | AU23: 37.4531 | AV23: NaN | AW23: 612.763 | AX23: 685.55 | AY23: NaN
A24: NPU | B24: det_seg | C24: 26 | D24: 1 | E24: 1 | F24: 0 | G24: 1 | H24: 1 | I24: 1 | J24: 1 | K24: 1 | L24: 1 | M24: 0 | N24: 0 | O24: 0 | P24: 0 | Q24: 609.075 | R24: 644.674 | S24: NaN | T24: 43.5123 | U24: 27.6699 | V24: 8250 | W24: 5793 | X24: 99.922 | Y24: 27.652 | Z24: 0.078 | AA24: 45.4337 | AB24: 13.826 | AC24: 23.682 | AD24: 33.383 | AE24: 16.514 | AF24: 13.792 | AG24: 25.024 | AH24: 181.184 | AI24: 2.207 | AJ24: NaN | AK24: NaN | AL24: NaN | AM24: NaN | AN24: 45.2067 | AO24: 45.2597 | AP24: NaN | AQ24: 5.60294 | AR24: 5.17437 | AS24: NaN | AT24: 0.0111264 | AU24: 37.2188 | AV24: NaN | AW24: 614.689 | AX24: 687.067 | AY24: NaN
A25: NPU | B25: det_seg | C25: 27 | D25: 1 | E25: 1 | F25: 0 | G25: 1 | H25: 1 | I25: 1 | J25: 1 | K25: 1 | L25: 1 | M25: 0 | N25: 0 | O25: 0 | P25: 0 | Q25: 607.846 | R25: 643.663 | S25: NaN | T25: 43.5843 | U25: 27.3872 | V25: 8260 | W25: 4732 | X25: 99.996 | Y25: 27.67 | Z25: 0.004 | AA25: 45.2962 | AB25: 13.818 | AC25: 23.737 | AD25: 30.886 | AE25: 16.257 | AF25: 13.818 | AG25: 25.968 | AH25: 196.175 | AI25: 2.205 | AJ25: NaN | AK25: NaN | AL25: NaN | AM25: NaN | AN25: 45.1222 | AO25: 45.1262 | AP25: NaN | AQ25: 5.64683 | AR25: 5.15043 | AS25: NaN | AT25: 0.0102898 | AU25: 37.1183 | AV25: NaN | AW25: 613.503 | AX25: 685.932 | AY25: NaN
A26: NPU | B26: det_pose | C26: 7 | D26: 1 | E26: 0 | F26: 1 | G26: 1 | H26: 1 | I26: 1 | J26: 1 | K26: 1 | L26: 1 | M26: 0 | N26: 0 | O26: 0 | P26: 0 | Q26: 670.94 | R26: NaN | S26: 675.776 | T26: 30.7228 | U26: 19.7797 | V26: 7830 | W26: 3405 | X26: NaN | Y26: NaN | Z26: NaN | AA26: 49.9109 | AB26: NaN | AC26: NaN | AD26: NaN | AE26: NaN | AF26: NaN | AG26: NaN | AH26: NaN | AI26: NaN | AJ26: NaN | AK26: NaN | AL26: NaN | AM26: NaN | AN26: 49.896 | AO26: NaN | AP26: 49.8432 | AQ26: 5.07818 | AR26: NaN | AS26: 5.28689 | AT26: 0.00949718 | AU26: NaN | AV26: 0.149182 | AW26: 676.028 | AX26: NaN | AY26: 681.212
A27: NPU | B27: det_pose | C27: 8 | D27: 1 | E27: 0 | F27: 1 | G27: 1 | H27: 1 | I27: 1 | J27: 1 | K27: 1 | L27: 1 | M27: 0 | N27: 0 | O27: 0 | P27: 0 | Q27: 670.712 | R27: NaN | S27: 676.795 | T27: 30.8054 | U27: 19.9369 | V27: 7822 | W27: 2724 | X27: NaN | Y27: NaN | Z27: NaN | AA27: 49.9145 | AB27: NaN | AC27: NaN | AD27: NaN | AE27: NaN | AF27: NaN | AG27: NaN | AH27: NaN | AI27: NaN | AJ27: NaN | AK27: NaN | AL27: NaN | AM27: NaN | AN27: 49.8498 | AO27: NaN | AP27: 49.8989 | AQ27: 5.04077 | AR27: NaN | AS27: 5.27848 | AT27: 0.00965498 | AU27: NaN | AV27: 0.154758 | AW27: 675.762 | AX27: NaN | AY27: 682.228
A28: NPU | B28: det_pose | C28: 9 | D28: 1 | E28: 0 | F28: 1 | G28: 1 | H28: 1 | I28: 1 | J28: 1 | K28: 1 | L28: 1 | M28: 0 | N28: 0 | O28: 0 | P28: 0 | Q28: 678.788 | R28: NaN | S28: 686.915 | T28: 30.8893 | U28: 19.8404 | V28: 7842 | W28: 2978 | X28: NaN | Y28: NaN | Z28: NaN | AA28: 50.5861 | AB28: NaN | AC28: NaN | AD28: NaN | AE28: NaN | AF28: NaN | AG28: NaN | AH28: NaN | AI28: NaN | AJ28: NaN | AK28: NaN | AL28: NaN | AM28: NaN | AN28: 50.4651 | AO28: NaN | AP28: 50.55 | AQ28: 5.04933 | AR28: NaN | AS28: 5.3281 | AT28: 0.0098175 | AU28: NaN | AV28: 0.165027 | AW28: 683.847 | AX28: NaN | AY28: 692.408
A29: NPU | B29: det_pose | C29: 28 | D29: 1 | E29: 0 | F29: 1 | G29: 1 | H29: 1 | I29: 1 | J29: 1 | K29: 1 | L29: 1 | M29: 0 | N29: 0 | O29: 0 | P29: 0 | Q29: 553.291 | R29: NaN | S29: 550.784 | T29: 30.475 | U29: 27.0526 | V29: 7649 | W29: 3421 | X29: 99.928 | Y29: 30.98 | Z29: 0.072 | AA29: 40.9888 | AB29: 15.49 | AC29: 23.077 | AD29: 27.182 | AE29: 14.95 | AF29: NaN | AG29: NaN | AH29: NaN | AI29: NaN | AJ29: 15.456 | AK29: 14.151 | AL29: 31.458 | AM29: 1.922 | AN29: 40.9589 | AO29: NaN | AP29: 40.9627 | AQ29: 5.04321 | AR29: NaN | AS29: 5.49584 | AT29: 0.00978957 | AU29: NaN | AV29: 0.155014 | AW29: 558.344 | AX29: NaN | AY29: 556.435
A30: NPU | B30: det_pose | C30: 29 | D30: 1 | E30: 0 | F30: 1 | G30: 1 | H30: 1 | I30: 1 | J30: 1 | K30: 1 | L30: 1 | M30: 0 | N30: 0 | O30: 0 | P30: 0 | Q30: 553.288 | R30: NaN | S30: 551.007 | T30: 30.5525 | U30: 26.9888 | V30: 7656 | W30: 3493 | X30: 99.882 | Y30: 30.992 | Z30: 0.119 | AA30: 40.9903 | AB30: 15.496 | AC30: 23.09 | AD30: 25.297 | AE30: 15.013 | AF30: NaN | AG30: NaN | AH30: NaN | AI30: NaN | AJ30: 15.463 | AK30: 14.098 | AL30: 31.546 | AM30: 1.944 | AN30: 40.9591 | AO30: NaN | AP30: 40.977 | AQ30: 5.05533 | AR30: NaN | AS30: 5.46352 | AT30: 0.00914022 | AU30: NaN | AV30: 0.151279 | AW30: 558.352 | AX30: NaN | AY30: 556.622
A31: NPU | B31: det_pose | C31: 30 | D31: 1 | E31: 0 | F31: 1 | G31: 1 | H31: 1 | I31: 1 | J31: 1 | K31: 1 | L31: 1 | M31: 0 | N31: 0 | O31: 0 | P31: 0 | Q31: 555.568 | R31: NaN | S31: 553.441 | T31: 30.3941 | U31: 26.9394 | V31: 7682 | W31: 2986 | X31: 99.936 | Y31: 30.785 | Z31: 0.064 | AA31: 41.1685 | AB31: 15.392 | AC31: 23.161 | AD31: 27.513 | AE31: 15.07 | AF31: NaN | AG31: NaN | AH31: NaN | AI31: NaN | AJ31: 15.392 | AK31: 14.133 | AL31: 32.694 | AM31: 2.032 | AN31: 41.1378 | AO31: NaN | AP31: 41.1537 | AQ31: 5.12751 | AR31: NaN | AS31: 5.47182 | AT31: 0.00917831 | AU31: NaN | AV31: 0.149077 | AW31: 560.704 | AX31: NaN | AY31: 559.062
A32: NPU | B32: det_seg_pose | C32: 10 | D32: 1 | E32: 1 | F32: 1 | G32: 1 | H32: 1 | I32: 1 | J32: 1 | K32: 1 | L32: 1 | M32: 0 | N32: 0 | O32: 0 | P32: 0 | Q32: 1316.89 | R32: 1347.83 | S32: 1336.28 | T32: 35.3621 | U32: 21.0261 | V32: 14749 | W32: 9201 | X32: 99.998 | Y32: 18.881 | Z32: 0.001 | AA32: 98.1239 | AB32: 6.29 | AC32: 26.103 | AD32: 36.533 | AE32: 15.408 | AF32: 6.29 | AG32: 33.727 | AH32: 69.868 | AI32: 1.993 | AJ32: 6.29 | AK32: 18.542 | AL32: 90.303 | AM32: 0.92 | AN32: 97.9959 | AO32: 97.948 | AP32: 97.9609 | AQ32: 5.39826 | AR32: 5.04146 | AS32: 6.33899 | AT32: 0.0108325 | AU32: 38.6711 | AV32: 0.157488 | AW32: 1322.3 | AX32: 1391.54 | AY32: 1342.78
A33: NPU | B33: det_seg_pose | C33: 11 | D33: 1 | E33: 1 | F33: 1 | G33: 1 | H33: 1 | I33: 1 | J33: 1 | K33: 1 | L33: 1 | M33: 0 | N33: 0 | O33: 0 | P33: 0 | Q33: 1310.46 | R33: 1341.12 | S33: 1329.67 | T33: 35.2474 | U33: 20.9594 | V33: 14748 | W33: 8188 | X33: 99.999 | Y33: 19.086 | Z33: 0.001 | AA33: 97.6495 | AB33: 6.358 | AC33: 26.002 | AD33: 37.42 | AE33: 15.52 | AF33: 6.358 | AG33: 33.445 | AH33: 63.052 | AI33: 2.153 | AJ33: 6.358 | AK33: 19.095 | AL33: 88.536 | AM33: 0.905 | AN33: 97.5137 | AO33: 97.4641 | AP33: 97.48 | AQ33: 5.34108 | AR33: 5.00279 | AS33: 6.3382 | AT33: 0.0102234 | AU33: 38.5808 | AV33: 0.166792 | AW33: 1315.81 | AX33: 1384.71 | AY33: 1336.17
A34: NPU | B34: det_seg_pose | C34: 12 | D34: 1 | E34: 1 | F34: 1 | G34: 1 | H34: 1 | I34: 1 | J34: 1 | K34: 1 | L34: 1 | M34: 0 | N34: 0 | O34: 0 | P34: 0 | Q34: 1311.05 | R34: 1342.36 | S34: 1329.97 | T34: 35.2565 | U34: 21.4062 | V34: 14661 | W34: 8735 | X34: 100 | Y34: 19.06 | Z34: 0 | AA34: 97.689 | AB34: 6.346 | AC34: 25.977 | AD34: 36.178 | AE34: 15.62 | AF34: 6.357 | AG34: 33.56 | AH34: 82.506 | AI34: 2.128 | AJ34: 6.346 | AK34: 18.772 | AL34: 77.706 | AM34: 0.91 | AN34: 97.5624 | AO34: 97.515 | AP34: 97.5303 | AQ34: 5.36398 | AR34: 4.98003 | AS34: 6.40936 | AT34: 0.0105456 | AU34: 38.7074 | AV34: 0.1514 | AW34: 1316.42 | AX34: 1386.05 | AY34: 1336.53
A35: CPU | B35: det | C35: 1 | D35: 1 | E35: 0 | F35: 0 | G35: 1 | H35: 1 | I35: 1 | J35: 1 | K35: 1 | L35: 1 | M35: 0 | N35: 0 | O35: 0 | P35: 0 | Q35: 6.15944 | R35: NaN | S35: NaN | T35: 59.4059 | U35: 12.4311 | V35: 944 | W35: 94 | X35: NaN | Y35: NaN | Z35: NaN | AA35: 3.56802 | AB35: NaN | AC35: NaN | AD35: NaN | AE35: NaN | AF35: NaN | AG35: NaN | AH35: NaN | AI35: NaN | AJ35: NaN | AK35: NaN | AL35: NaN | AM35: NaN | AN35: 3.55612 | AO35: NaN | AP35: NaN | AQ35: 4.56615 | AR35: NaN | AS35: NaN | AT35: 0.00757852 | AU35: NaN | AV35: NaN | AW35: 10.7332 | AX35: NaN | AY35: NaN
A36: CPU | B36: det | C36: 2 | D36: 1 | E36: 0 | F36: 0 | G36: 1 | H36: 1 | I36: 1 | J36: 1 | K36: 1 | L36: 1 | M36: 0 | N36: 0 | O36: 0 | P36: 0 | Q36: 5.99142 | R36: NaN | S36: NaN | T36: 59.9174 | U36: 11.3561 | V36: 909 | W36: 83 | X36: NaN | Y36: NaN | Z36: NaN | AA36: 3.60851 | AB36: NaN | AC36: NaN | AD36: NaN | AE36: NaN | AF36: NaN | AG36: NaN | AH36: NaN | AI36: NaN | AJ36: NaN | AK36: NaN | AL36: NaN | AM36: NaN | AN36: 3.59658 | AO36: NaN | AP36: NaN | AQ36: 4.62475 | AR36: NaN | AS36: NaN | AT36: 0.00686605 | AU36: NaN | AV36: NaN | AW36: 10.623 | AX36: NaN | AY36: NaN
A37: CPU | B37: det | C37: 3 | D37: 1 | E37: 0 | F37: 0 | G37: 1 | H37: 1 | I37: 1 | J37: 1 | K37: 1 | L37: 1 | M37: 0 | N37: 0 | O37: 0 | P37: 0 | Q37: 6.08704 | R37: NaN | S37: NaN | T37: 59.8177 | U37: 11.1108 | V37: 807 | W37: 64 | X37: NaN | Y37: NaN | Z37: NaN | AA37: 3.59465 | AB37: NaN | AC37: NaN | AD37: NaN | AE37: NaN | AF37: NaN | AG37: NaN | AH37: NaN | AI37: NaN | AJ37: NaN | AK37: NaN | AL37: NaN | AM37: NaN | AN37: 3.58267 | AO37: NaN | AP37: NaN | AQ37: 4.60567 | AR37: NaN | AS37: NaN | AT37: 0.00847092 | AU37: NaN | AV37: NaN | AW37: 10.7012 | AX37: NaN | AY37: NaN
A38: CPU | B38: det | C38: 13 | D38: 1 | E38: 0 | F38: 0 | G38: 1 | H38: 1 | I38: 1 | J38: 1 | K38: 1 | L38: 1 | M38: 0 | N38: 0 | O38: 0 | P38: 0 | Q38: 5.9686 | R38: NaN | S38: NaN | T38: 58.8194 | U38: 19.4505 | V38: 903 | W38: 364 | X38: NaN | Y38: NaN | Z38: NaN | AA38: 3.59814 | AB38: NaN | AC38: NaN | AD38: NaN | AE38: NaN | AF38: NaN | AG38: NaN | AH38: NaN | AI38: NaN | AJ38: NaN | AK38: NaN | AL38: NaN | AM38: NaN | AN38: 3.58596 | AO38: NaN | AP38: NaN | AQ38: 4.60325 | AR38: NaN | AS38: NaN | AT38: 0.00801819 | AU38: NaN | AV38: NaN | AW38: 10.5799 | AX38: NaN | AY38: NaN
A39: CPU | B39: det | C39: 14 | D39: 1 | E39: 0 | F39: 0 | G39: 1 | H39: 1 | I39: 1 | J39: 1 | K39: 1 | L39: 1 | M39: 0 | N39: 0 | O39: 0 | P39: 0 | Q39: 6.03226 | R39: NaN | S39: NaN | T39: 59.8361 | U39: 18.0923 | V39: 886 | W39: 311 | X39: NaN | Y39: NaN | Z39: NaN | AA39: 3.65778 | AB39: NaN | AC39: NaN | AD39: NaN | AE39: NaN | AF39: NaN | AG39: NaN | AH39: NaN | AI39: NaN | AJ39: NaN | AK39: NaN | AL39: NaN | AM39: NaN | AN39: 3.6415 | AO39: NaN | AP39: NaN | AQ39: 4.68847 | AR39: NaN | AS39: NaN | AT39: 0.00839583 | AU39: NaN | AV39: NaN | AW39: 10.7291 | AX39: NaN | AY39: NaN
A40: CPU | B40: det | C40: 15 | D40: 1 | E40: 0 | F40: 0 | G40: 1 | H40: 1 | I40: 1 | J40: 1 | K40: 1 | L40: 1 | M40: 0 | N40: 0 | O40: 0 | P40: 0 | Q40: 5.99901 | R40: NaN | S40: NaN | T40: 59.7637 | U40: 18.0828 | V40: 782 | W40: 138 | X40: NaN | Y40: NaN | Z40: NaN | AA40: 3.63195 | AB40: NaN | AC40: NaN | AD40: NaN | AE40: NaN | AF40: NaN | AG40: NaN | AH40: NaN | AI40: NaN | AJ40: NaN | AK40: NaN | AL40: NaN | AM40: NaN | AN40: 3.61989 | AO40: NaN | AP40: NaN | AQ40: 4.65564 | AR40: NaN | AS40: NaN | AT40: 0.00733764 | AU40: NaN | AV40: NaN | AW40: 10.662 | AX40: NaN | AY40: NaN
A41: CPU | B41: det | C41: 16 | D41: 1 | E41: 0 | F41: 0 | G41: 1 | H41: 1 | I41: 1 | J41: 1 | K41: 1 | L41: 1 | M41: 0 | N41: 0 | O41: 0 | P41: 0 | Q41: 6.11283 | R41: NaN | S41: NaN | T41: 60 | U41: 18.0857 | V41: 917 | W41: 148 | X41: NaN | Y41: NaN | Z41: NaN | AA41: 3.57962 | AB41: NaN | AC41: NaN | AD41: NaN | AE41: NaN | AF41: NaN | AG41: NaN | AH41: NaN | AI41: NaN | AJ41: NaN | AK41: NaN | AL41: NaN | AM41: NaN | AN41: 3.56761 | AO41: NaN | AP41: NaN | AQ41: 4.58139 | AR41: NaN | AS41: NaN | AT41: 0.00827938 | AU41: NaN | AV41: NaN | AW41: 10.7025 | AX41: NaN | AY41: NaN
A42: CPU | B42: det | C42: 17 | D42: 1 | E42: 0 | F42: 0 | G42: 1 | H42: 1 | I42: 1 | J42: 1 | K42: 1 | L42: 1 | M42: 0 | N42: 0 | O42: 0 | P42: 0 | Q42: 6.10069 | R42: NaN | S42: NaN | T42: 60.3981 | U42: 18.1005 | V42: 824 | W42: 281 | X42: NaN | Y42: NaN | Z42: NaN | AA42: 3.65599 | AB42: NaN | AC42: NaN | AD42: NaN | AE42: NaN | AF42: NaN | AG42: NaN | AH42: NaN | AI42: NaN | AJ42: NaN | AK42: NaN | AL42: NaN | AM42: NaN | AN42: 3.64354 | AO42: NaN | AP42: NaN | AQ42: 4.67937 | AR42: NaN | AS42: NaN | AT42: 0.00809872 | AU42: NaN | AV42: NaN | AW42: 10.7882 | AX42: NaN | AY42: NaN
...

Sheet 케이스별_평균
A1: postprocess_engine | B1: combo | C1: n_total_rows | D1: n_hrtt_rows | E1: use_det_avg | F1: use_seg_avg | G1: use_pose_avg | H1: batch_det_avg | I1: batch_seg_avg | J1: batch_pose_avg | K1: threshold_det_avg | L1: threshold_seg_avg | M1: threshold_pose_avg | N1: timeout_ms_avg | O1: priority_det_avg | P1: priority_seg_avg | Q1: priority_pose_avg | R1: det_latency_ms_avg | S1: seg_latency_ms_avg | T1: pose_latency_ms_avg | U1: cpu_percent_avg | V1: mem_percent_avg | W1: voluntary_ctx_switches_avg | X1: nonvoluntary_ctx_switches_avg | Y1: npu_percent_avg | Z1: switches_per_s_avg | AA1: idle_time_pct_avg | AB1: run_time_s_avg | AC1: avg_fps_det_avg | AD1: avg_latency_det_avg | AE1: max_latency_det_avg | AF1: activation_det_avg | AG1: avg_fps_seg_avg | AH1: avg_latency_seg_avg | AI1: max_latency_seg_avg | AJ1: activation_seg_avg | AK1: avg_fps_pose_avg | AL1: avg_latency_pose_avg | AM1: max_latency_pose_avg | AN1: activation_pose_avg | AO1: total_time_det_s_avg | AP1: total_time_seg_s_avg | AQ1: total_time_pose_s_avg | AR1: avg_preprocess_ms_det_avg | AS1: avg_preprocess_ms_seg_avg | AT1: avg_preprocess_ms_pose_avg | AU1: postprocess_ms_det_avg | AV1: postprocess_ms_seg_avg | AW1: postprocess_ms_pose_avg | AX1: total_time_ms_det_avg | AY1: total_time_ms_seg_avg | AZ1: total_time_ms_pose_avg
A2: NPU | B2: det | C2: =COUNTIFS(전체!$A$2:$A$67,$A2,전체!$B$2:$B$67,$B2) -> 18 | D2: =COUNTIFS(전체!$A$2:$A$67,$A2,전체!$B$2:$B$67,$B2,전체!$X$2:$X$67,"<>NaN") -> 3 | E2: =IFERROR(AVERAGEIFS(전체!$D$2:$D$67,전체!$A$2:$A$67,$A2,전체!$B$2:$B$67,$B2),"-") -> 1 | F2: =IFERROR(AVERAGEIFS(전체!$E$2:$E$67,전체!$A$2:$A$67,$A2,전체!$B$2:$B$67,$B2),"-") -> 0 | G2: =IFERROR(AVERAGEIFS(전체!$F$2:$F$67,전체!$A$2:$A$67,$A2,전체!$B$2:$B$67,$B2),"-") -> 0 | H2: =IFERROR(AVERAGEIFS(전체!$G$2:$G$67,전체!$A$2:$A$67,$A2,전체!$B$2:$B$67,$B2),"-") -> 1 | I2: =IFERROR(AVERAGEIFS(전체!$H$2:$H$67,전체!$A$2:$A$67,$A2,전체!$B$2:$B$67,$B2),"-") -> 1 | J2: =IFERROR(AVERAGEIFS(전체!$I$2:$I$67,전체!$A$2:$A$67,$A2,전체!$B$2:$B$67,$B2),"-") -> 1 | K2: =IFERROR(AVERAGEIFS(전체!$J$2:$J$67,전체!$A$2:$A$67,$A2,전체!$B$2:$B$67,$B2),"-") -> 1 | L2: =IFERROR(AVERAGEIFS(전체!$K$2:$K$67,전체!$A$2:$A$67,$A2,전체!$B$2:$B$67,$B2),"-") -> 1 | M2: =IFERROR(AVERAGEIFS(전체!$L$2:$L$67,전체!$A$2:$A$67,$A2,전체!$B$2:$B$67,$B2),"-") -> 1 | N2: =IFERROR(AVERAGEIFS(전체!$M$2:$M$67,전체!$A$2:$A$67,$A2,전체!$B$2:$B$67,$B2),"-") -> 0 | O2: =IFERROR(AVERAGEIFS(전체!$N$2:$N$67,전체!$A$2:$A$67,$A2,전체!$B$2:$B$67,$B2),"-") -> 0 | P2: =IFERROR(AVERAGEIFS(전체!$O$2:$O$67,전체!$A$2:$A$67,$A2,전체!$B$2:$B$67,$B2),"-") -> 0 | Q2: =IFERROR(AVERAGEIFS(전체!$P$2:$P$67,전체!$A$2:$A$67,$A2,전체!$B$2:$B$67,$B2),"-") -> 0 | R2: =IFERROR(AVERAGEIFS(전체!$Q$2:$Q$67,전체!$A$2:$A$67,$A2,전체!$B$2:$B$67,$B2),"-") -> 152.77122 | S2: =IFERROR(AVERAGEIFS(전체!$R$2:$R$67,전체!$A$2:$A$67,$A2,전체!$B$2:$B$67,$B2),"-") -> - | T2: =IFERROR(AVERAGEIFS(전체!$S$2:$S$67,전체!$A$2:$A$67,$A2,전체!$B$2:$B$67,$B2),"-") -> - | U2: =IFERROR(AVERAGEIFS(전체!$T$2:$T$67,전체!$A$2:$A$67,$A2,전체!$B$2:$B$67,$B2),"-") -> 23.096378 | V2: =IFERROR(AVERAGEIFS(전체!$U$2:$U$67,전체!$A$2:$A$67,$A2,전체!$B$2:$B$67,$B2),"-") -> 25.7646 | W2: =IFERROR(AVERAGEIFS(전체!$V$2:$V$67,전체!$A$2:$A$67,$A2,전체!$B$2:$B$67,$B2),"-") -> 1336.3333 | X2: =IFERROR(AVERAGEIFS(전체!$W$2:$W$67,전체!$A$2:$A$67,$A2,전체!$B$2:$B$67,$B2),"-") -> 717.05556 | Y2: =IFERROR(AVERAGEIFS(전체!$X$2:$X$67,전체!$A$2:$A$67,$A2,전체!$B$2:$B$67,$B2),"-") -> 99.336667 | Z2: =IFERROR(AVERAGEIFS(전체!$Y$2:$Y$67,전체!$A$2:$A$67,$A2,전체!$B$2:$B$67,$B2),"-") -> 0.35866667 | AA2: =IFERROR(AVERAGEIFS(전체!$Z$2:$Z$67,전체!$A$2:$A$67,$A2,전체!$B$2:$B$67,$B2),"-") -> 0.66333333 | AB2: =IFERROR(AVERAGEIFS(전체!$AA$2:$AA$67,전체!$A$2:$A$67,$A2,전체!$B$2:$B$67,$B2),"-") -> 9.6228178 | AC2: =IFERROR(AVERAGEIFS(전체!$AB$2:$AB$67,전체!$A$2:$A$67,$A2,전체!$B$2:$B$67,$B2),"-") -> 69.518333 | AD2: =IFERROR(AVERAGEIFS(전체!$AC$2:$AC$67,전체!$A$2:$A$67,$A2,전체!$B$2:$B$67,$B2),"-") -> 111.06867 | AE2: =IFERROR(AVERAGEIFS(전체!$AD$2:$AD$67,전체!$A$2:$A$67,$A2,전체!$B$2:$B$67,$B2),"-") -> 116.466 | AF2: =IFERROR(AVERAGEIFS(전체!$AE$2:$AE$67,전체!$A$2:$A$67,$A2,전체!$B$2:$B$67,$B2),"-") -> 18.502333 | AG2: =IFERROR(AVERAGEIFS(전체!$AF$2:$AF$67,전체!$A$2:$A$67,$A2,전체!$B$2:$B$67,$B2),"-") -> - | AH2: =IFERROR(AVERAGEIFS(전체!$AG$2:$AG$67,전체!$A$2:$A$67,$A2,전체!$B$2:$B$67,$B2),"-") -> - | AI2: =IFERROR(AVERAGEIFS(전체!$AH$2:$AH$67,전체!$A$2:$A$67,$A2,전체!$B$2:$B$67,$B2),"-") -> - | AJ2: =IFERROR(AVERAGEIFS(전체!$AI$2:$AI$67,전체!$A$2:$A$67,$A2,전체!$B$2:$B$67,$B2),"-") -> - | AK2: =IFERROR(AVERAGEIFS(전체!$AJ$2:$AJ$67,전체!$A$2:$A$67,$A2,전체!$B$2:$B$67,$B2),"-") -> - | AL2: =IFERROR(AVERAGEIFS(전체!$AK$2:$AK$67,전체!$A$2:$A$67,$A2,전체!$B$2:$B$67,$B2),"-") -> - | AM2: =IFERROR(AVERAGEIFS(전체!$AL$2:$AL$67,전체!$A$2:$A$67,$A2,전체!$B$2:$B$67,$B2),"-") -> - | AN2: =IFERROR(AVERAGEIFS(전체!$AM$2:$AM$67,전체!$A$2:$A$67,$A2,전체!$B$2:$B$67,$B2),"-") -> - | AO2: =IFERROR(AVERAGEIFS(전체!$AN$2:$AN$67,전체!$A$2:$A$67,$A2,전체!$B$2:$B$67,$B2),"-") -> 9.6105722 | AP2: =IFERROR(AVERAGEIFS(전체!$AO$2:$AO$67,전체!$A$2:$A$67,$A2,전체!$B$2:$B$67,$B2),"-") -> - | AQ2: =IFERROR(AVERAGEIFS(전체!$AP$2:$AP$67,전체!$A$2:$A$67,$A2,전체!$B$2:$B$67,$B2),"-") -> - | AR2: =IFERROR(AVERAGEIFS(전체!$AQ$2:$AQ$67,전체!$A$2:$A$67,$A2,전체!$B$2:$B$67,$B2),"-") -> 4.9839933 | AS2: =IFERROR(AVERAGEIFS(전체!$AR$2:$AR$67,전체!$A$2:$A$67,$A2,전체!$B$2:$B$67,$B2),"-") -> - | AT2: =IFERROR(AVERAGEIFS(전체!$AS$2:$AS$67,전체!$A$2:$A$67,$A2,전체!$B$2:$B$67,$B2),"-") -> - | AU2: =IFERROR(AVERAGEIFS(전체!$AT$2:$AT$67,전체!$A$2:$A$67,$A2,전체!$B$2:$B$67,$B2),"-") -> 0.010174079 | AV2: =IFERROR(AVERAGEIFS(전체!$AU$2:$AU$67,전체!$A$2:$A$67,$A2,전체!$B$2:$B$67,$B2),"-") -> - | AW2: =IFERROR(AVERAGEIFS(전체!$AV$2:$AV$67,전체!$A$2:$A$67,$A2,전체!$B$2:$B$67,$B2),"-") -> - | AX2: =IFERROR(AVERAGEIFS(전체!$AW$2:$AW$67,전체!$A$2:$A$67,$A2,전체!$B$2:$B$67,$B2),"-") -> 157.76528 | AY2: =IFERROR(AVERAGEIFS(전체!$AX$2:$AX$67,전체!$A$2:$A$67,$A2,전체!$B$2:$B$67,$B2),"-") -> - | AZ2: =IFERROR(AVERAGEIFS(전체!$AY$2:$AY$67,전체!$A$2:$A$67,$A2,전체!$B$2:$B$67,$B2),"-") -> -
A3: NPU | B3: det_seg | C3: =COUNTIFS(전체!$A$2:$A$67,$A3,전체!$B$2:$B$67,$B3) -> 6 | D3: =COUNTIFS(전체!$A$2:$A$67,$A3,전체!$B$2:$B$67,$B3,전체!$X$2:$X$67,"<>NaN") -> 3 | E3: =IFERROR(AVERAGEIFS(전체!$D$2:$D$67,전체!$A$2:$A$67,$A3,전체!$B$2:$B$67,$B3),"-") -> 1 | F3: =IFERROR(AVERAGEIFS(전체!$E$2:$E$67,전체!$A$2:$A$67,$A3,전체!$B$2:$B$67,$B3),"-") -> 1 | G3: =IFERROR(AVERAGEIFS(전체!$F$2:$F$67,전체!$A$2:$A$67,$A3,전체!$B$2:$B$67,$B3),"-") -> 0 | H3: =IFERROR(AVERAGEIFS(전체!$G$2:$G$67,전체!$A$2:$A$67,$A3,전체!$B$2:$B$67,$B3),"-") -> 1 | I3: =IFERROR(AVERAGEIFS(전체!$H$2:$H$67,전체!$A$2:$A$67,$A3,전체!$B$2:$B$67,$B3),"-") -> 1 | J3: =IFERROR(AVERAGEIFS(전체!$I$2:$I$67,전체!$A$2:$A$67,$A3,전체!$B$2:$B$67,$B3),"-") -> 1 | K3: =IFERROR(AVERAGEIFS(전체!$J$2:$J$67,전체!$A$2:$A$67,$A3,전체!$B$2:$B$67,$B3),"-") -> 1 | L3: =IFERROR(AVERAGEIFS(전체!$K$2:$K$67,전체!$A$2:$A$67,$A3,전체!$B$2:$B$67,$B3),"-") -> 1 | M3: =IFERROR(AVERAGEIFS(전체!$L$2:$L$67,전체!$A$2:$A$67,$A3,전체!$B$2:$B$67,$B3),"-") -> 1 | N3: =IFERROR(AVERAGEIFS(전체!$M$2:$M$67,전체!$A$2:$A$67,$A3,전체!$B$2:$B$67,$B3),"-") -> 0 | O3: =IFERROR(AVERAGEIFS(전체!$N$2:$N$67,전체!$A$2:$A$67,$A3,전체!$B$2:$B$67,$B3),"-") -> 0 | P3: =IFERROR(AVERAGEIFS(전체!$O$2:$O$67,전체!$A$2:$A$67,$A3,전체!$B$2:$B$67,$B3),"-") -> 0 | Q3: =IFERROR(AVERAGEIFS(전체!$P$2:$P$67,전체!$A$2:$A$67,$A3,전체!$B$2:$B$67,$B3),"-") -> 0 | R3: =IFERROR(AVERAGEIFS(전체!$Q$2:$Q$67,전체!$A$2:$A$67,$A3,전체!$B$2:$B$67,$B3),"-") -> 700.20033 | S3: =IFERROR(AVERAGEIFS(전체!$R$2:$R$67,전체!$A$2:$A$67,$A3,전체!$B$2:$B$67,$B3),"-") -> 734.76717 | T3: =IFERROR(AVERAGEIFS(전체!$S$2:$S$67,전체!$A$2:$A$67,$A3,전체!$B$2:$B$67,$B3),"-") -> - | U3: =IFERROR(AVERAGEIFS(전체!$T$2:$T$67,전체!$A$2:$A$67,$A3,전체!$B$2:$B$67,$B3),"-") -> 42.185433 | V3: =IFERROR(AVERAGEIFS(전체!$U$2:$U$67,전체!$A$2:$A$67,$A3,전체!$B$2:$B$67,$B3),"-") -> 23.951983 | W3: =IFERROR(AVERAGEIFS(전체!$V$2:$V$67,전체!$A$2:$A$67,$A3,전체!$B$2:$B$67,$B3),"-") -> 8218.8333 | X3: =IFERROR(AVERAGEIFS(전체!$W$2:$W$67,전체!$A$2:$A$67,$A3,전체!$B$2:$B$67,$B3),"-") -> 5343.3333 | Y3: =IFERROR(AVERAGEIFS(전체!$X$2:$X$67,전체!$A$2:$A$67,$A3,전체!$B$2:$B$67,$B3),"-") -> 99.943333 | Z3: =IFERROR(AVERAGEIFS(전체!$Y$2:$Y$67,전체!$A$2:$A$67,$A3,전체!$B$2:$B$67,$B3),"-") -> 27.686 | AA3: =IFERROR(AVERAGEIFS(전체!$Z$2:$Z$67,전체!$A$2:$A$67,$A3,전체!$B$2:$B$67,$B3),"-") -> 0.056666667 | AB3: =IFERROR(AVERAGEIFS(전체!$AA$2:$AA$67,전체!$A$2:$A$67,$A3,전체!$B$2:$B$67,$B3),"-") -> 52.266067 | AC3: =IFERROR(AVERAGEIFS(전체!$AB$2:$AB$67,전체!$A$2:$A$67,$A3,전체!$B$2:$B$67,$B3),"-") -> 13.831667 | AD3: =IFERROR(AVERAGEIFS(전체!$AC$2:$AC$67,전체!$A$2:$A$67,$A3,전체!$B$2:$B$67,$B3),"-") -> 23.702 | AE3: =IFERROR(AVERAGEIFS(전체!$AD$2:$AD$67,전체!$A$2:$A$67,$A3,전체!$B$2:$B$67,$B3),"-") -> 32.451667 | AF3: =IFERROR(AVERAGEIFS(전체!$AE$2:$AE$67,전체!$A$2:$A$67,$A3,전체!$B$2:$B$67,$B3),"-") -> 16.419 | AG3: =IFERROR(AVERAGEIFS(전체!$AF$2:$AF$67,전체!$A$2:$A$67,$A3,전체!$B$2:$B$67,$B3),"-") -> 13.820333 | AH3: =IFERROR(AVERAGEIFS(전체!$AG$2:$AG$67,전체!$A$2:$A$67,$A3,전체!$B$2:$B$67,$B3),"-") -> 25.383333 | AI3: =IFERROR(AVERAGEIFS(전체!$AH$2:$AH$67,전체!$A$2:$A$67,$A3,전체!$B$2:$B$67,$B3),"-") -> 182.39733 | AJ3: =IFERROR(AVERAGEIFS(전체!$AI$2:$AI$67,전체!$A$2:$A$67,$A3,전체!$B$2:$B$67,$B3),"-") -> 2.1166667 | AK3: =IFERROR(AVERAGEIFS(전체!$AJ$2:$AJ$67,전체!$A$2:$A$67,$A3,전체!$B$2:$B$67,$B3),"-") -> - | AL3: =IFERROR(AVERAGEIFS(전체!$AK$2:$AK$67,전체!$A$2:$A$67,$A3,전체!$B$2:$B$67,$B3),"-") -> - | AM3: =IFERROR(AVERAGEIFS(전체!$AL$2:$AL$67,전체!$A$2:$A$67,$A3,전체!$B$2:$B$67,$B3),"-") -> - | AN3: =IFERROR(AVERAGEIFS(전체!$AM$2:$AM$67,전체!$A$2:$A$67,$A3,전체!$B$2:$B$67,$B3),"-") -> - | AO3: =IFERROR(AVERAGEIFS(전체!$AN$2:$AN$67,전체!$A$2:$A$67,$A3,전체!$B$2:$B$67,$B3),"-") -> 52.100667 | AP3: =IFERROR(AVERAGEIFS(전체!$AO$2:$AO$67,전체!$A$2:$A$67,$A3,전체!$B$2:$B$67,$B3),"-") -> 52.094167 | AQ3: =IFERROR(AVERAGEIFS(전체!$AP$2:$AP$67,전체!$A$2:$A$67,$A3,전체!$B$2:$B$67,$B3),"-") -> - | AR3: =IFERROR(AVERAGEIFS(전체!$AQ$2:$AQ$67,전체!$A$2:$A$67,$A3,전체!$B$2:$B$67,$B3),"-") -> 5.5863 | AS3: =IFERROR(AVERAGEIFS(전체!$AR$2:$AR$67,전체!$A$2:$A$67,$A3,전체!$B$2:$B$67,$B3),"-") -> 5.16355 | AT3: =IFERROR(AVERAGEIFS(전체!$AS$2:$AS$67,전체!$A$2:$A$67,$A3,전체!$B$2:$B$67,$B3),"-") -> - | AU3: =IFERROR(AVERAGEIFS(전체!$AT$2:$AT$67,전체!$A$2:$A$67,$A3,전체!$B$2:$B$67,$B3),"-") -> 0.010595033 | AV3: =IFERROR(AVERAGEIFS(전체!$AU$2:$AU$67,전체!$A$2:$A$67,$A3,전체!$B$2:$B$67,$B3),"-") -> 37.427283 | AW3: =IFERROR(AVERAGEIFS(전체!$AV$2:$AV$67,전체!$A$2:$A$67,$A3,전체!$B$2:$B$67,$B3),"-") -> - | AX3: =IFERROR(AVERAGEIFS(전체!$AW$2:$AW$67,전체!$A$2:$A$67,$A3,전체!$B$2:$B$67,$B3),"-") -> 705.797 | AY3: =IFERROR(AVERAGEIFS(전체!$AX$2:$AX$67,전체!$A$2:$A$67,$A3,전체!$B$2:$B$67,$B3),"-") -> 777.358 | AZ3: =IFERROR(AVERAGEIFS(전체!$AY$2:$AY$67,전체!$A$2:$A$67,$A3,전체!$B$2:$B$67,$B3),"-") -> -
A4: NPU | B4: det_pose | C4: =COUNTIFS(전체!$A$2:$A$67,$A4,전체!$B$2:$B$67,$B4) -> 6 | D4: =COUNTIFS(전체!$A$2:$A$67,$A4,전체!$B$2:$B$67,$B4,전체!$X$2:$X$67,"<>NaN") -> 3 | E4: =IFERROR(AVERAGEIFS(전체!$D$2:$D$67,전체!$A$2:$A$67,$A4,전체!$B$2:$B$67,$B4),"-") -> 1 | F4: =IFERROR(AVERAGEIFS(전체!$E$2:$E$67,전체!$A$2:$A$67,$A4,전체!$B$2:$B$67,$B4),"-") -> 0 | G4: =IFERROR(AVERAGEIFS(전체!$F$2:$F$67,전체!$A$2:$A$67,$A4,전체!$B$2:$B$67,$B4),"-") -> 1 | H4: =IFERROR(AVERAGEIFS(전체!$G$2:$G$67,전체!$A$2:$A$67,$A4,전체!$B$2:$B$67,$B4),"-") -> 1 | I4: =IFERROR(AVERAGEIFS(전체!$H$2:$H$67,전체!$A$2:$A$67,$A4,전체!$B$2:$B$67,$B4),"-") -> 1 | J4: =IFERROR(AVERAGEIFS(전체!$I$2:$I$67,전체!$A$2:$A$67,$A4,전체!$B$2:$B$67,$B4),"-") -> 1 | K4: =IFERROR(AVERAGEIFS(전체!$J$2:$J$67,전체!$A$2:$A$67,$A4,전체!$B$2:$B$67,$B4),"-") -> 1 | L4: =IFERROR(AVERAGEIFS(전체!$K$2:$K$67,전체!$A$2:$A$67,$A4,전체!$B$2:$B$67,$B4),"-") -> 1 | M4: =IFERROR(AVERAGEIFS(전체!$L$2:$L$67,전체!$A$2:$A$67,$A4,전체!$B$2:$B$67,$B4),"-") -> 1 | N4: =IFERROR(AVERAGEIFS(전체!$M$2:$M$67,전체!$A$2:$A$67,$A4,전체!$B$2:$B$67,$B4),"-") -> 0 | O4: =IFERROR(AVERAGEIFS(전체!$N$2:$N$67,전체!$A$2:$A$67,$A4,전체!$B$2:$B$67,$B4),"-") -> 0 | P4: =IFERROR(AVERAGEIFS(전체!$O$2:$O$67,전체!$A$2:$A$67,$A4,전체!$B$2:$B$67,$B4),"-") -> 0 | Q4: =IFERROR(AVERAGEIFS(전체!$P$2:$P$67,전체!$A$2:$A$67,$A4,전체!$B$2:$B$67,$B4),"-") -> 0 | R4: =IFERROR(AVERAGEIFS(전체!$Q$2:$Q$67,전체!$A$2:$A$67,$A4,전체!$B$2:$B$67,$B4),"-") -> 613.7645 | S4: =IFERROR(AVERAGEIFS(전체!$R$2:$R$67,전체!$A$2:$A$67,$A4,전체!$B$2:$B$67,$B4),"-") -> - | T4: =IFERROR(AVERAGEIFS(전체!$S$2:$S$67,전체!$A$2:$A$67,$A4,전체!$B$2:$B$67,$B4),"-") -> 615.78633 | U4: =IFERROR(AVERAGEIFS(전체!$T$2:$T$67,전체!$A$2:$A$67,$A4,전체!$B$2:$B$67,$B4),"-") -> 30.63985 | V4: =IFERROR(AVERAGEIFS(전체!$U$2:$U$67,전체!$A$2:$A$67,$A4,전체!$B$2:$B$67,$B4),"-") -> 23.422967 | W4: =IFERROR(AVERAGEIFS(전체!$V$2:$V$67,전체!$A$2:$A$67,$A4,전체!$B$2:$B$67,$B4),"-") -> 7746.8333 | X4: =IFERROR(AVERAGEIFS(전체!$W$2:$W$67,전체!$A$2:$A$67,$A4,전체!$B$2:$B$67,$B4),"-") -> 3167.8333 | Y4: =IFERROR(AVERAGEIFS(전체!$X$2:$X$67,전체!$A$2:$A$67,$A4,전체!$B$2:$B$67,$B4),"-") -> 99.915333 | Z4: =IFERROR(AVERAGEIFS(전체!$Y$2:$Y$67,전체!$A$2:$A$67,$A4,전체!$B$2:$B$67,$B4),"-") -> 30.919 | AA4: =IFERROR(AVERAGEIFS(전체!$Z$2:$Z$67,전체!$A$2:$A$67,$A4,전체!$B$2:$B$67,$B4),"-") -> 0.085 | AB4: =IFERROR(AVERAGEIFS(전체!$AA$2:$AA$67,전체!$A$2:$A$67,$A4,전체!$B$2:$B$67,$B4),"-") -> 45.593183 | AC4: =IFERROR(AVERAGEIFS(전체!$AB$2:$AB$67,전체!$A$2:$A$67,$A4,전체!$B$2:$B$67,$B4),"-") -> 15.459333 | AD4: =IFERROR(AVERAGEIFS(전체!$AC$2:$AC$67,전체!$A$2:$A$67,$A4,전체!$B$2:$B$67,$B4),"-") -> 23.109333 | AE4: =IFERROR(AVERAGEIFS(전체!$AD$2:$AD$67,전체!$A$2:$A$67,$A4,전체!$B$2:$B$67,$B4),"-") -> 26.664 | AF4: =IFERROR(AVERAGEIFS(전체!$AE$2:$AE$67,전체!$A$2:$A$67,$A4,전체!$B$2:$B$67,$B4),"-") -> 15.011 | AG4: =IFERROR(AVERAGEIFS(전체!$AF$2:$AF$67,전체!$A$2:$A$67,$A4,전체!$B$2:$B$67,$B4),"-") -> - | AH4: =IFERROR(AVERAGEIFS(전체!$AG$2:$AG$67,전체!$A$2:$A$67,$A4,전체!$B$2:$B$67,$B4),"-") -> - | AI4: =IFERROR(AVERAGEIFS(전체!$AH$2:$AH$67,전체!$A$2:$A$67,$A4,전체!$B$2:$B$67,$B4),"-") -> - | AJ4: =IFERROR(AVERAGEIFS(전체!$AI$2:$AI$67,전체!$A$2:$A$67,$A4,전체!$B$2:$B$67,$B4),"-") -> - | AK4: =IFERROR(AVERAGEIFS(전체!$AJ$2:$AJ$67,전체!$A$2:$A$67,$A4,전체!$B$2:$B$67,$B4),"-") -> 15.437 | AL4: =IFERROR(AVERAGEIFS(전체!$AK$2:$AK$67,전체!$A$2:$A$67,$A4,전체!$B$2:$B$67,$B4),"-") -> 14.127333 | AM4: =IFERROR(AVERAGEIFS(전체!$AL$2:$AL$67,전체!$A$2:$A$67,$A4,전체!$B$2:$B$67,$B4),"-") -> 31.899333 | AN4: =IFERROR(AVERAGEIFS(전체!$AM$2:$AM$67,전체!$A$2:$A$67,$A4,전체!$B$2:$B$67,$B4),"-") -> 1.966 | AO4: =IFERROR(AVERAGEIFS(전체!$AN$2:$AN$67,전체!$A$2:$A$67,$A4,전체!$B$2:$B$67,$B4),"-") -> 45.54445 | AP4: =IFERROR(AVERAGEIFS(전체!$AO$2:$AO$67,전체!$A$2:$A$67,$A4,전체!$B$2:$B$67,$B4),"-") -> - | AQ4: =IFERROR(AVERAGEIFS(전체!$AP$2:$AP$67,전체!$A$2:$A$67,$A4,전체!$B$2:$B$67,$B4),"-") -> 45.56425 | AR4: =IFERROR(AVERAGEIFS(전체!$AQ$2:$AQ$67,전체!$A$2:$A$67,$A4,전체!$B$2:$B$67,$B4),"-") -> 5.0657217 | AS4: =IFERROR(AVERAGEIFS(전체!$AR$2:$AR$67,전체!$A$2:$A$67,$A4,전체!$B$2:$B$67,$B4),"-") -> - | AT4: =IFERROR(AVERAGEIFS(전체!$AS$2:$AS$67,전체!$A$2:$A$67,$A4,전체!$B$2:$B$67,$B4),"-") -> 5.3874417 | AU4: =IFERROR(AVERAGEIFS(전체!$AT$2:$AT$67,전체!$A$2:$A$67,$A4,전체!$B$2:$B$67,$B4),"-") -> 0.00951296 | AV4: =IFERROR(AVERAGEIFS(전체!$AU$2:$AU$67,전체!$A$2:$A$67,$A4,전체!$B$2:$B$67,$B4),"-") -> - | AW4: =IFERROR(AVERAGEIFS(전체!$AV$2:$AV$67,전체!$A$2:$A$67,$A4,전체!$B$2:$B$67,$B4),"-") -> 0.15405617 | AX4: =IFERROR(AVERAGEIFS(전체!$AW$2:$AW$67,전체!$A$2:$A$67,$A4,전체!$B$2:$B$67,$B4),"-") -> 618.8395 | AY4: =IFERROR(AVERAGEIFS(전체!$AX$2:$AX$67,전체!$A$2:$A$67,$A4,전체!$B$2:$B$67,$B4),"-") -> - | AZ4: =IFERROR(AVERAGEIFS(전체!$AY$2:$AY$67,전체!$A$2:$A$67,$A4,전체!$B$2:$B$67,$B4),"-") -> 621.32783
A5: NPU | B5: det_seg_pose | C5: =COUNTIFS(전체!$A$2:$A$67,$A5,전체!$B$2:$B$67,$B5) -> 3 | D5: =COUNTIFS(전체!$A$2:$A$67,$A5,전체!$B$2:$B$67,$B5,전체!$X$2:$X$67,"<>NaN") -> 3 | E5: =IFERROR(AVERAGEIFS(전체!$D$2:$D$67,전체!$A$2:$A$67,$A5,전체!$B$2:$B$67,$B5),"-") -> 1 | F5: =IFERROR(AVERAGEIFS(전체!$E$2:$E$67,전체!$A$2:$A$67,$A5,전체!$B$2:$B$67,$B5),"-") -> 1 | G5: =IFERROR(AVERAGEIFS(전체!$F$2:$F$67,전체!$A$2:$A$67,$A5,전체!$B$2:$B$67,$B5),"-") -> 1 | H5: =IFERROR(AVERAGEIFS(전체!$G$2:$G$67,전체!$A$2:$A$67,$A5,전체!$B$2:$B$67,$B5),"-") -> 1 | I5: =IFERROR(AVERAGEIFS(전체!$H$2:$H$67,전체!$A$2:$A$67,$A5,전체!$B$2:$B$67,$B5),"-") -> 1 | J5: =IFERROR(AVERAGEIFS(전체!$I$2:$I$67,전체!$A$2:$A$67,$A5,전체!$B$2:$B$67,$B5),"-") -> 1 | K5: =IFERROR(AVERAGEIFS(전체!$J$2:$J$67,전체!$A$2:$A$67,$A5,전체!$B$2:$B$67,$B5),"-") -> 1 | L5: =IFERROR(AVERAGEIFS(전체!$K$2:$K$67,전체!$A$2:$A$67,$A5,전체!$B$2:$B$67,$B5),"-") -> 1 | M5: =IFERROR(AVERAGEIFS(전체!$L$2:$L$67,전체!$A$2:$A$67,$A5,전체!$B$2:$B$67,$B5),"-") -> 1 | N5: =IFERROR(AVERAGEIFS(전체!$M$2:$M$67,전체!$A$2:$A$67,$A5,전체!$B$2:$B$67,$B5),"-") -> 0 | O5: =IFERROR(AVERAGEIFS(전체!$N$2:$N$67,전체!$A$2:$A$67,$A5,전체!$B$2:$B$67,$B5),"-") -> 0 | P5: =IFERROR(AVERAGEIFS(전체!$O$2:$O$67,전체!$A$2:$A$67,$A5,전체!$B$2:$B$67,$B5),"-") -> 0 | Q5: =IFERROR(AVERAGEIFS(전체!$P$2:$P$67,전체!$A$2:$A$67,$A5,전체!$B$2:$B$67,$B5),"-") -> 0 | R5: =IFERROR(AVERAGEIFS(전체!$Q$2:$Q$67,전체!$A$2:$A$67,$A5,전체!$B$2:$B$67,$B5),"-") -> 1312.8 | S5: =IFERROR(AVERAGEIFS(전체!$R$2:$R$67,전체!$A$2:$A$67,$A5,전체!$B$2:$B$67,$B5),"-") -> 1343.77 | T5: =IFERROR(AVERAGEIFS(전체!$S$2:$S$67,전체!$A$2:$A$67,$A5,전체!$B$2:$B$67,$B5),"-") -> 1331.9733 | U5: =IFERROR(AVERAGEIFS(전체!$T$2:$T$67,전체!$A$2:$A$67,$A5,전체!$B$2:$B$67,$B5),"-") -> 35.288667 | V5: =IFERROR(AVERAGEIFS(전체!$U$2:$U$67,전체!$A$2:$A$67,$A5,전체!$B$2:$B$67,$B5),"-") -> 21.130567 | W5: =IFERROR(AVERAGEIFS(전체!$V$2:$V$67,전체!$A$2:$A$67,$A5,전체!$B$2:$B$67,$B5),"-") -> 14719.333 | X5: =IFERROR(AVERAGEIFS(전체!$W$2:$W$67,전체!$A$2:$A$67,$A5,전체!$B$2:$B$67,$B5),"-") -> 8708 | Y5: =IFERROR(AVERAGEIFS(전체!$X$2:$X$67,전체!$A$2:$A$67,$A5,전체!$B$2:$B$67,$B5),"-") -> 99.999 | Z5: =IFERROR(AVERAGEIFS(전체!$Y$2:$Y$67,전체!$A$2:$A$67,$A5,전체!$B$2:$B$67,$B5),"-") -> 19.009 | AA5: =IFERROR(AVERAGEIFS(전체!$Z$2:$Z$67,전체!$A$2:$A$67,$A5,전체!$B$2:$B$67,$B5),"-") -> 0.00066666667 | AB5: =IFERROR(AVERAGEIFS(전체!$AA$2:$AA$67,전체!$A$2:$A$67,$A5,전체!$B$2:$B$67,$B5),"-") -> 97.8208 | AC5: =IFERROR(AVERAGEIFS(전체!$AB$2:$AB$67,전체!$A$2:$A$67,$A5,전체!$B$2:$B$67,$B5),"-") -> 6.3313333 | AD5: =IFERROR(AVERAGEIFS(전체!$AC$2:$AC$67,전체!$A$2:$A$67,$A5,전체!$B$2:$B$67,$B5),"-") -> 26.027333 | AE5: =IFERROR(AVERAGEIFS(전체!$AD$2:$AD$67,전체!$A$2:$A$67,$A5,전체!$B$2:$B$67,$B5),"-") -> 36.710333 | AF5: =IFERROR(AVERAGEIFS(전체!$AE$2:$AE$67,전체!$A$2:$A$67,$A5,전체!$B$2:$B$67,$B5),"-") -> 15.516 | AG5: =IFERROR(AVERAGEIFS(전체!$AF$2:$AF$67,전체!$A$2:$A$67,$A5,전체!$B$2:$B$67,$B5),"-") -> 6.335 | AH5: =IFERROR(AVERAGEIFS(전체!$AG$2:$AG$67,전체!$A$2:$A$67,$A5,전체!$B$2:$B$67,$B5),"-") -> 33.577333 | AI5: =IFERROR(AVERAGEIFS(전체!$AH$2:$AH$67,전체!$A$2:$A$67,$A5,전체!$B$2:$B$67,$B5),"-") -> 71.808667 | AJ5: =IFERROR(AVERAGEIFS(전체!$AI$2:$AI$67,전체!$A$2:$A$67,$A5,전체!$B$2:$B$67,$B5),"-") -> 2.0913333 | AK5: =IFERROR(AVERAGEIFS(전체!$AJ$2:$AJ$67,전체!$A$2:$A$67,$A5,전체!$B$2:$B$67,$B5),"-") -> 6.3313333 | AL5: =IFERROR(AVERAGEIFS(전체!$AK$2:$AK$67,전체!$A$2:$A$67,$A5,전체!$B$2:$B$67,$B5),"-") -> 18.803 | AM5: =IFERROR(AVERAGEIFS(전체!$AL$2:$AL$67,전체!$A$2:$A$67,$A5,전체!$B$2:$B$67,$B5),"-") -> 85.515 | AN5: =IFERROR(AVERAGEIFS(전체!$AM$2:$AM$67,전체!$A$2:$A$67,$A5,전체!$B$2:$B$67,$B5),"-") -> 0.91166667 | AO5: =IFERROR(AVERAGEIFS(전체!$AN$2:$AN$67,전체!$A$2:$A$67,$A5,전체!$B$2:$B$67,$B5),"-") -> 97.690667 | AP5: =IFERROR(AVERAGEIFS(전체!$AO$2:$AO$67,전체!$A$2:$A$67,$A5,전체!$B$2:$B$67,$B5),"-") -> 97.642367 | AQ5: =IFERROR(AVERAGEIFS(전체!$AP$2:$AP$67,전체!$A$2:$A$67,$A5,전체!$B$2:$B$67,$B5),"-") -> 97.657067 | AR5: =IFERROR(AVERAGEIFS(전체!$AQ$2:$AQ$67,전체!$A$2:$A$67,$A5,전체!$B$2:$B$67,$B5),"-") -> 5.3677733 | AS5: =IFERROR(AVERAGEIFS(전체!$AR$2:$AR$67,전체!$A$2:$A$67,$A5,전체!$B$2:$B$67,$B5),"-") -> 5.0080933 | AT5: =IFERROR(AVERAGEIFS(전체!$AS$2:$AS$67,전체!$A$2:$A$67,$A5,전체!$B$2:$B$67,$B5),"-") -> 6.3621833 | AU5: =IFERROR(AVERAGEIFS(전체!$AT$2:$AT$67,전체!$A$2:$A$67,$A5,전체!$B$2:$B$67,$B5),"-") -> 0.010533833 | AV5: =IFERROR(AVERAGEIFS(전체!$AU$2:$AU$67,전체!$A$2:$A$67,$A5,전체!$B$2:$B$67,$B5),"-") -> 38.6531 | AW5: =IFERROR(AVERAGEIFS(전체!$AV$2:$AV$67,전체!$A$2:$A$67,$A5,전체!$B$2:$B$67,$B5),"-") -> 0.15856 | AX5: =IFERROR(AVERAGEIFS(전체!$AW$2:$AW$67,전체!$A$2:$A$67,$A5,전체!$B$2:$B$67,$B5),"-") -> 1318.1767 | AY5: =IFERROR(AVERAGEIFS(전체!$AX$2:$AX$67,전체!$A$2:$A$67,$A5,전체!$B$2:$B$67,$B5),"-") -> 1387.4333 | AZ5: =IFERROR(AVERAGEIFS(전체!$AY$2:$AY$67,전체!$A$2:$A$67,$A5,전체!$B$2:$B$67,$B5),"-") -> 1338.4933
A6: CPU | B6: det | C6: =COUNTIFS(전체!$A$2:$A$67,$A6,전체!$B$2:$B$67,$B6) -> 18 | D6: =COUNTIFS(전체!$A$2:$A$67,$A6,전체!$B$2:$B$67,$B6,전체!$X$2:$X$67,"<>NaN") -> 3 | E6: =IFERROR(AVERAGEIFS(전체!$D$2:$D$67,전체!$A$2:$A$67,$A6,전체!$B$2:$B$67,$B6),"-") -> 1 | F6: =IFERROR(AVERAGEIFS(전체!$E$2:$E$67,전체!$A$2:$A$67,$A6,전체!$B$2:$B$67,$B6),"-") -> 0 | G6: =IFERROR(AVERAGEIFS(전체!$F$2:$F$67,전체!$A$2:$A$67,$A6,전체!$B$2:$B$67,$B6),"-") -> 0 | H6: =IFERROR(AVERAGEIFS(전체!$G$2:$G$67,전체!$A$2:$A$67,$A6,전체!$B$2:$B$67,$B6),"-") -> 1 | I6: =IFERROR(AVERAGEIFS(전체!$H$2:$H$67,전체!$A$2:$A$67,$A6,전체!$B$2:$B$67,$B6),"-") -> 1 | J6: =IFERROR(AVERAGEIFS(전체!$I$2:$I$67,전체!$A$2:$A$67,$A6,전체!$B$2:$B$67,$B6),"-") -> 1 | K6: =IFERROR(AVERAGEIFS(전체!$J$2:$J$67,전체!$A$2:$A$67,$A6,전체!$B$2:$B$67,$B6),"-") -> 1 | L6: =IFERROR(AVERAGEIFS(전체!$K$2:$K$67,전체!$A$2:$A$67,$A6,전체!$B$2:$B$67,$B6),"-") -> 1 | M6: =IFERROR(AVERAGEIFS(전체!$L$2:$L$67,전체!$A$2:$A$67,$A6,전체!$B$2:$B$67,$B6),"-") -> 1 | N6: =IFERROR(AVERAGEIFS(전체!$M$2:$M$67,전체!$A$2:$A$67,$A6,전체!$B$2:$B$67,$B6),"-") -> 0 | O6: =IFERROR(AVERAGEIFS(전체!$N$2:$N$67,전체!$A$2:$A$67,$A6,전체!$B$2:$B$67,$B6),"-") -> 0 | P6: =IFERROR(AVERAGEIFS(전체!$O$2:$O$67,전체!$A$2:$A$67,$A6,전체!$B$2:$B$67,$B6),"-") -> 0 | Q6: =IFERROR(AVERAGEIFS(전체!$P$2:$P$67,전체!$A$2:$A$67,$A6,전체!$B$2:$B$67,$B6),"-") -> 0 | R6: =IFERROR(AVERAGEIFS(전체!$Q$2:$Q$67,전체!$A$2:$A$67,$A6,전체!$B$2:$B$67,$B6),"-") -> 5.9650239 | S6: =IFERROR(AVERAGEIFS(전체!$R$2:$R$67,전체!$A$2:$A$67,$A6,전체!$B$2:$B$67,$B6),"-") -> - | T6: =IFERROR(AVERAGEIFS(전체!$S$2:$S$67,전체!$A$2:$A$67,$A6,전체!$B$2:$B$67,$B6),"-") -> - | U6: =IFERROR(AVERAGEIFS(전체!$T$2:$T$67,전체!$A$2:$A$67,$A6,전체!$B$2:$B$67,$B6),"-") -> 59.546222 | V6: =IFERROR(AVERAGEIFS(전체!$U$2:$U$67,전체!$A$2:$A$67,$A6,전체!$B$2:$B$67,$B6),"-") -> 17.183094 | W6: =IFERROR(AVERAGEIFS(전체!$V$2:$V$67,전체!$A$2:$A$67,$A6,전체!$B$2:$B$67,$B6),"-") -> 885.22222 | X6: =IFERROR(AVERAGEIFS(전체!$W$2:$W$67,전체!$A$2:$A$67,$A6,전체!$B$2:$B$67,$B6),"-") -> 179.88889 | Y6: =IFERROR(AVERAGEIFS(전체!$X$2:$X$67,전체!$A$2:$A$67,$A6,전체!$B$2:$B$67,$B6),"-") -> 99.994 | Z6: =IFERROR(AVERAGEIFS(전체!$Y$2:$Y$67,전체!$A$2:$A$67,$A6,전체!$B$2:$B$67,$B6),"-") -> 0.56633333 | AA6: =IFERROR(AVERAGEIFS(전체!$Z$2:$Z$67,전체!$A$2:$A$67,$A6,전체!$B$2:$B$67,$B6),"-") -> 0.006 | AB6: =IFERROR(AVERAGEIFS(전체!$AA$2:$AA$67,전체!$A$2:$A$67,$A6,전체!$B$2:$B$67,$B6),"-") -> 3.6034978 | AC6: =IFERROR(AVERAGEIFS(전체!$AB$2:$AB$67,전체!$A$2:$A$67,$A6,전체!$B$2:$B$67,$B6),"-") -> 188.09367 | AD6: =IFERROR(AVERAGEIFS(전체!$AC$2:$AC$67,전체!$A$2:$A$67,$A6,전체!$B$2:$B$67,$B6),"-") -> 4.0846667 | AE6: =IFERROR(AVERAGEIFS(전체!$AD$2:$AD$67,전체!$A$2:$A$67,$A6,전체!$B$2:$B$67,$B6),"-") -> 13.943667 | AF6: =IFERROR(AVERAGEIFS(전체!$AE$2:$AE$67,전체!$A$2:$A$67,$A6,전체!$B$2:$B$67,$B6),"-") -> 0.17333333 | AG6: =IFERROR(AVERAGEIFS(전체!$AF$2:$AF$67,전체!$A$2:$A$67,$A6,전체!$B$2:$B$67,$B6),"-") -> - | AH6: =IFERROR(AVERAGEIFS(전체!$AG$2:$AG$67,전체!$A$2:$A$67,$A6,전체!$B$2:$B$67,$B6),"-") -> - | AI6: =IFERROR(AVERAGEIFS(전체!$AH$2:$AH$67,전체!$A$2:$A$67,$A6,전체!$B$2:$B$67,$B6),"-") -> - | AJ6: =IFERROR(AVERAGEIFS(전체!$AI$2:$AI$67,전체!$A$2:$A$67,$A6,전체!$B$2:$B$67,$B6),"-") -> - | AK6: =IFERROR(AVERAGEIFS(전체!$AJ$2:$AJ$67,전체!$A$2:$A$67,$A6,전체!$B$2:$B$67,$B6),"-") -> - | AL6: =IFERROR(AVERAGEIFS(전체!$AK$2:$AK$67,전체!$A$2:$A$67,$A6,전체!$B$2:$B$67,$B6),"-") -> - | AM6: =IFERROR(AVERAGEIFS(전체!$AL$2:$AL$67,전체!$A$2:$A$67,$A6,전체!$B$2:$B$67,$B6),"-") -> - | AN6: =IFERROR(AVERAGEIFS(전체!$AM$2:$AM$67,전체!$A$2:$A$67,$A6,전체!$B$2:$B$67,$B6),"-") -> - | AO6: =IFERROR(AVERAGEIFS(전체!$AN$2:$AN$67,전체!$A$2:$A$67,$A6,전체!$B$2:$B$67,$B6),"-") -> 3.5912317 | AP6: =IFERROR(AVERAGEIFS(전체!$AO$2:$AO$67,전체!$A$2:$A$67,$A6,전체!$B$2:$B$67,$B6),"-") -> - | AQ6: =IFERROR(AVERAGEIFS(전체!$AP$2:$AP$67,전체!$A$2:$A$67,$A6,전체!$B$2:$B$67,$B6),"-") -> - | AR6: =IFERROR(AVERAGEIFS(전체!$AQ$2:$AQ$67,전체!$A$2:$A$67,$A6,전체!$B$2:$B$67,$B6),"-") -> 4.6155294 | AS6: =IFERROR(AVERAGEIFS(전체!$AR$2:$AR$67,전체!$A$2:$A$67,$A6,전체!$B$2:$B$67,$B6),"-") -> - | AT6: =IFERROR(AVERAGEIFS(전체!$AS$2:$AS$67,전체!$A$2:$A$67,$A6,전체!$B$2:$B$67,$B6),"-") -> - | AU6: =IFERROR(AVERAGEIFS(전체!$AT$2:$AT$67,전체!$A$2:$A$67,$A6,전체!$B$2:$B$67,$B6),"-") -> 0.00802887 | AV6: =IFERROR(AVERAGEIFS(전체!$AU$2:$AU$67,전체!$A$2:$A$67,$A6,전체!$B$2:$B$67,$B6),"-") -> - | AW6: =IFERROR(AVERAGEIFS(전체!$AV$2:$AV$67,전체!$A$2:$A$67,$A6,전체!$B$2:$B$67,$B6),"-") -> - | AX6: =IFERROR(AVERAGEIFS(전체!$AW$2:$AW$67,전체!$A$2:$A$67,$A6,전체!$B$2:$B$67,$B6),"-") -> 10.588589 | AY6: =IFERROR(AVERAGEIFS(전체!$AX$2:$AX$67,전체!$A$2:$A$67,$A6,전체!$B$2:$B$67,$B6),"-") -> - | AZ6: =IFERROR(AVERAGEIFS(전체!$AY$2:$AY$67,전체!$A$2:$A$67,$A6,전체!$B$2:$B$67,$B6),"-") -> -
A7: CPU | B7: det_seg | C7: =COUNTIFS(전체!$A$2:$A$67,$A7,전체!$B$2:$B$67,$B7) -> 6 | D7: =COUNTIFS(전체!$A$2:$A$67,$A7,전체!$B$2:$B$67,$B7,전체!$X$2:$X$67,"<>NaN") -> 3 | E7: =IFERROR(AVERAGEIFS(전체!$D$2:$D$67,전체!$A$2:$A$67,$A7,전체!$B$2:$B$67,$B7),"-") -> 1 | F7: =IFERROR(AVERAGEIFS(전체!$E$2:$E$67,전체!$A$2:$A$67,$A7,전체!$B$2:$B$67,$B7),"-") -> 1 | G7: =IFERROR(AVERAGEIFS(전체!$F$2:$F$67,전체!$A$2:$A$67,$A7,전체!$B$2:$B$67,$B7),"-") -> 0 | H7: =IFERROR(AVERAGEIFS(전체!$G$2:$G$67,전체!$A$2:$A$67,$A7,전체!$B$2:$B$67,$B7),"-") -> 1 | I7: =IFERROR(AVERAGEIFS(전체!$H$2:$H$67,전체!$A$2:$A$67,$A7,전체!$B$2:$B$67,$B7),"-") -> 1 | J7: =IFERROR(AVERAGEIFS(전체!$I$2:$I$67,전체!$A$2:$A$67,$A7,전체!$B$2:$B$67,$B7),"-") -> 1 | K7: =IFERROR(AVERAGEIFS(전체!$J$2:$J$67,전체!$A$2:$A$67,$A7,전체!$B$2:$B$67,$B7),"-") -> 1 | L7: =IFERROR(AVERAGEIFS(전체!$K$2:$K$67,전체!$A$2:$A$67,$A7,전체!$B$2:$B$67,$B7),"-") -> 1 | M7: =IFERROR(AVERAGEIFS(전체!$L$2:$L$67,전체!$A$2:$A$67,$A7,전체!$B$2:$B$67,$B7),"-") -> 1 | N7: =IFERROR(AVERAGEIFS(전체!$M$2:$M$67,전체!$A$2:$A$67,$A7,전체!$B$2:$B$67,$B7),"-") -> 0 | O7: =IFERROR(AVERAGEIFS(전체!$N$2:$N$67,전체!$A$2:$A$67,$A7,전체!$B$2:$B$67,$B7),"-") -> 0 | P7: =IFERROR(AVERAGEIFS(전체!$O$2:$O$67,전체!$A$2:$A$67,$A7,전체!$B$2:$B$67,$B7),"-") -> 0 | Q7: =IFERROR(AVERAGEIFS(전체!$P$2:$P$67,전체!$A$2:$A$67,$A7,전체!$B$2:$B$67,$B7),"-") -> 0 | R7: =IFERROR(AVERAGEIFS(전체!$Q$2:$Q$67,전체!$A$2:$A$67,$A7,전체!$B$2:$B$67,$B7),"-") -> 610.53117 | S7: =IFERROR(AVERAGEIFS(전체!$R$2:$R$67,전체!$A$2:$A$67,$A7,전체!$B$2:$B$67,$B7),"-") -> 693.2175 | T7: =IFERROR(AVERAGEIFS(전체!$S$2:$S$67,전체!$A$2:$A$67,$A7,전체!$B$2:$B$67,$B7),"-") -> - | U7: =IFERROR(AVERAGEIFS(전체!$T$2:$T$67,전체!$A$2:$A$67,$A7,전체!$B$2:$B$67,$B7),"-") -> 41.0608 | V7: =IFERROR(AVERAGEIFS(전체!$U$2:$U$67,전체!$A$2:$A$67,$A7,전체!$B$2:$B$67,$B7),"-") -> 15.853617 | W7: =IFERROR(AVERAGEIFS(전체!$V$2:$V$67,전체!$A$2:$A$67,$A7,전체!$B$2:$B$67,$B7),"-") -> 8368.3333 | X7: =IFERROR(AVERAGEIFS(전체!$W$2:$W$67,전체!$A$2:$A$67,$A7,전체!$B$2:$B$67,$B7),"-") -> 6736.8333 | Y7: =IFERROR(AVERAGEIFS(전체!$X$2:$X$67,전체!$A$2:$A$67,$A7,전체!$B$2:$B$67,$B7),"-") -> 99.999333 | Z7: =IFERROR(AVERAGEIFS(전체!$Y$2:$Y$67,전체!$A$2:$A$67,$A7,전체!$B$2:$B$67,$B7),"-") -> 33.405 | AA7: =IFERROR(AVERAGEIFS(전체!$Z$2:$Z$67,전체!$A$2:$A$67,$A7,전체!$B$2:$B$67,$B7),"-") -> 0.001 | AB7: =IFERROR(AVERAGEIFS(전체!$AA$2:$AA$67,전체!$A$2:$A$67,$A7,전체!$B$2:$B$67,$B7),"-") -> 42.156967 | AC7: =IFERROR(AVERAGEIFS(전체!$AB$2:$AB$67,전체!$A$2:$A$67,$A7,전체!$B$2:$B$67,$B7),"-") -> 17.768 | AD7: =IFERROR(AVERAGEIFS(전체!$AC$2:$AC$67,전체!$A$2:$A$67,$A7,전체!$B$2:$B$67,$B7),"-") -> 17.469 | AE7: =IFERROR(AVERAGEIFS(전체!$AD$2:$AD$67,전체!$A$2:$A$67,$A7,전체!$B$2:$B$67,$B7),"-") -> 36.875 | AF7: =IFERROR(AVERAGEIFS(전체!$AE$2:$AE$67,전체!$A$2:$A$67,$A7,전체!$B$2:$B$67,$B7),"-") -> 0.61866667 | AG7: =IFERROR(AVERAGEIFS(전체!$AF$2:$AF$67,전체!$A$2:$A$67,$A7,전체!$B$2:$B$67,$B7),"-") -> 16.708333 | AH7: =IFERROR(AVERAGEIFS(전체!$AG$2:$AG$67,전체!$A$2:$A$67,$A7,전체!$B$2:$B$67,$B7),"-") -> 68.562667 | AI7: =IFERROR(AVERAGEIFS(전체!$AH$2:$AH$67,전체!$A$2:$A$67,$A7,전체!$B$2:$B$67,$B7),"-") -> 457.49533 | AJ7: =IFERROR(AVERAGEIFS(전체!$AI$2:$AI$67,전체!$A$2:$A$67,$A7,전체!$B$2:$B$67,$B7),"-") -> 0.75466667 | AK7: =IFERROR(AVERAGEIFS(전체!$AJ$2:$AJ$67,전체!$A$2:$A$67,$A7,전체!$B$2:$B$67,$B7),"-") -> - | AL7: =IFERROR(AVERAGEIFS(전체!$AK$2:$AK$67,전체!$A$2:$A$67,$A7,전체!$B$2:$B$67,$B7),"-") -> - | AM7: =IFERROR(AVERAGEIFS(전체!$AL$2:$AL$67,전체!$A$2:$A$67,$A7,전체!$B$2:$B$67,$B7),"-") -> - | AN7: =IFERROR(AVERAGEIFS(전체!$AM$2:$AM$67,전체!$A$2:$A$67,$A7,전체!$B$2:$B$67,$B7),"-") -> - | AO7: =IFERROR(AVERAGEIFS(전체!$AN$2:$AN$67,전체!$A$2:$A$67,$A7,전체!$B$2:$B$67,$B7),"-") -> 37.654033 | AP7: =IFERROR(AVERAGEIFS(전체!$AO$2:$AO$67,전체!$A$2:$A$67,$A7,전체!$B$2:$B$67,$B7),"-") -> 41.9852 | AQ7: =IFERROR(AVERAGEIFS(전체!$AP$2:$AP$67,전체!$A$2:$A$67,$A7,전체!$B$2:$B$67,$B7),"-") -> - | AR7: =IFERROR(AVERAGEIFS(전체!$AQ$2:$AQ$67,전체!$A$2:$A$67,$A7,전체!$B$2:$B$67,$B7),"-") -> 6.634415 | AS7: =IFERROR(AVERAGEIFS(전체!$AR$2:$AR$67,전체!$A$2:$A$67,$A7,전체!$B$2:$B$67,$B7),"-") -> 5.69291 | AT7: =IFERROR(AVERAGEIFS(전체!$AS$2:$AS$67,전체!$A$2:$A$67,$A7,전체!$B$2:$B$67,$B7),"-") -> - | AU7: =IFERROR(AVERAGEIFS(전체!$AT$2:$AT$67,전체!$A$2:$A$67,$A7,전체!$B$2:$B$67,$B7),"-") -> 0.011504703 | AV7: =IFERROR(AVERAGEIFS(전체!$AU$2:$AU$67,전체!$A$2:$A$67,$A7,전체!$B$2:$B$67,$B7),"-") -> 37.966167 | AW7: =IFERROR(AVERAGEIFS(전체!$AV$2:$AV$67,전체!$A$2:$A$67,$A7,전체!$B$2:$B$67,$B7),"-") -> - | AX7: =IFERROR(AVERAGEIFS(전체!$AW$2:$AW$67,전체!$A$2:$A$67,$A7,전체!$B$2:$B$67,$B7),"-") -> 617.17683 | AY7: =IFERROR(AVERAGEIFS(전체!$AX$2:$AX$67,전체!$A$2:$A$67,$A7,전체!$B$2:$B$67,$B7),"-") -> 736.87633 | AZ7: =IFERROR(AVERAGEIFS(전체!$AY$2:$AY$67,전체!$A$2:$A$67,$A7,전체!$B$2:$B$67,$B7),"-") -> -
